Workbook
Name ____________DAD11: #REF!
Name _________DAD11: #REF!
Name _________DAD11: #REF!
Name _________DAD11: #REF!
Name _________DAD11: #REF!
Name _________DAD11: #REF!
Name _________DAD11: #REF!
Name _________DAD11: #REF!
Name _________DAD11: #REF!
Name ________DAD11: #REF!
Name _____DAD11: #REF!
Name ____DAD11: #REF!
Name ___DAD11: #REF!
Name __DAD11: #REF!
Name _DAD11: #REF!
Name a: #REF!
Name a: #REF!
Name a: #REF!
Name a: #REF!
Name a: #REF!
Name a: #REF!
Name a: #REF!
Name a: #REF!
Name AA: #REF!
Name AA: #REF!
Name AA: #REF!
Name AA: #REF!
Name AA: #REF!
Name AA: #REF!
Name AA: #REF!
Name AA: #REF!
Name aaa: #REF!
Name aaa: #REF!
Name aaa: #REF!
Name aaa: #REF!
Name aaa: #REF!
Name aaa: #REF!
Name aaa: #REF!
Name aaa: #REF!
Name ADNAN: '[1]Main 1'!$M$68
Name B: #REF!
Name B: #REF!
Name B: #REF!
Name B: #REF!
Name B: #REF!
Name B: #REF!
Name B: #REF!
Name B: #REF!
Name ccc: #REF!
Name ccc: #REF!
Name ccc: #REF!
Name ccc: #REF!
Name ccc: #REF!
Name ccc: #REF!
Name ccc: #REF!
Name ccc: #REF!
Name ccc: #REF!
Name ccc: #REF!
Name ccc: #REF!
Name ccc: #REF!

Sheet Title
A1: HITACHI | H1: CT / VT | O1: Contract No. | R1: N-19957.1-DF5W
H2: ADEQUACY CHECK | O2: Date | R2: 46106
H3: LT14 - LEWIS 400/132kV SUBSTATION | O3: Document No. | R3: -
O4: Revision No. | R4: A
A5: Prep. By | C5: AP | D5: Checked By | G5: RB | H5: Title Sheet | O5: Contractor | R5: HITACHI
E17: =H3 -> LT14 - LEWIS 400/132kV SUBSTATION
E19: CT/VT ADEQUACY CHECK
L21: CT & VT CALCULATIONS
M33: Hitachi
M34: Substation Automation Systems
M36: Date: | P36: =R2 -> 46106
M37: Prepared by: | P37: Arulprakasam K
M38: Checked by: | P38: Ramesh Babu
M39: Approved by: | P39: Rudresh N

Sheet INDEX
A1: HITACHI | H1: =Title!H1 -> CT / VT | O1: =Title!O1 -> Contract No. | R1: =Title!R1 -> N-19957.1-DF5W
H2: =Title!H2 -> ADEQUACY CHECK | O2: =Title!O2 -> Date | R2: =Title!R2 -> 46106
H3: =Title!H3 -> LT14 - LEWIS 400/132kV SUBSTATION | O3: =Title!O3 -> Document No. | R3: =Title!R3 -> -
O4: =Title!O4 -> Revision No. | R4: =Title!R4 -> A
A5: =Title!A5 -> Prep. By | C5: =Title!C5 -> AP | D5: =Title!D5 -> Checked By | G5: =Title!G5 -> RB | H5: Index | O5: =Title!O5 -> Contractor | R5: =Title!R5 -> HITACHI
C8: INDEX
R10: Pg:No
C11: 1 | D11: NOTES | N11: Page 4 of 25 | R11: 3
C12: 2 | D12: SUMMARY SHEET | N12: Page 5 of 25 | R12: 4 | Y12: CT / VT Data Summary
C13: 3 | D13: CT/VT BURDEN DETAILS | Q13: - | R13: 11
C14: 4 | D14: CT ADEQUACY CHECK | R14: 13
C15: 5 | D15: PARAMETERS AND FAULT CALCULATIONS | Q15: - | R15: 14 | Y15: Parameters & Fault Calculations
C16: 6 | D16: BUS SECTION COUPLER | R16: 18
C17: 7 | D17: TRANSFORMER FEEDER | R17: 30
C18: 8 | D18: LINE PROTECTION 400KV FEEDERS | R18: 40
C19: 9 | D19: LINE PROTECTION HVDC FEEDERS | R19: 59
C20: 10 | D20: VT ADEQUACY CHECK | R20: 78
C21: 11 | D21: HVDC FEEDER VT | R21: 79
C22: 12 | D22: FEEDER VT | R22: 84
C23: 13 | D23: SGT 1,2 &3 VT | R23: 89
AD30: Supporting Documents
C31: ANNEXURE-A | G31: Over All SLD | R31: 92 | AD31: Annexure- A | AG31: Relays Burden
C32: ANNEXURE-B | G32: Input requirements list | R32: 94 | AD32: Annexure- B | AG32: CT requirements of RET670
C33: ANNEXURE-C | G33: CT requirements of RED670 | R33: 99 | AD33: Annexure- C | AG33: CT requirements of RET615
C34: ANNEXURE-D | G34: CT requirements of REF650 | R34: 109 | AD34: Annexure- D | AG34: CT requirements of REF615
C35: ANNEXURE-E | G35: CT requirements of REC670 | R35: 119 | AD35: Annexure- E | AG35: ESI Standard 48-3
C36: ANNEXURE-F | G36: CT requirements of REB500 | R36: 123
C37: ANNEXURE-G | G37: CT requirements of P545 | R37: 127 | AD37: Annexure- E | AG37: ESI Standard 48-3
C38: ANNEXURE-H | G38: CT requirements of 7SL86 | R38: 249 | AD38: Annexure- F | AG38: 220kV SS-516 SLD
C39: ANNEXURE-I | G39: CT requirements of SEL487E | R39: 255
C40: ANNEXURE-H | G40: CT requirements of IDM+X | R40: 137
C41: ANNEXURE-I | G41: CT requirements of P743 | R41: 142
C42: ANNEXURE-J | G42: CT requirements of MFAC | R42: 147

Sheet Notes Or Assumptions
A1: HITACHI | H1: =Title!H1 -> CT / VT | O1: =Title!O1 -> Contract No. | R1: =Title!R1 -> N-19957.1-DF5W
H2: =Title!H2 -> ADEQUACY CHECK | O2: =Title!O2 -> Date | R2: =Title!R2 -> 46106
H3: =Title!H3 -> LT14 - LEWIS 400/132kV SUBSTATION | O3: =Title!O3 -> Document No. | R3: =Title!R3 -> -
O4: =Title!O4 -> Revision No. | R4: =Title!R4 -> A
A5: =Title!A5 -> Prep. By | C5: =Title!C5 -> AP | D5: =Title!D5 -> Checked By | G5: =Title!G5 -> RB | H5: Notes | O5: =Title!O5 -> Contractor | R5: =Title!R5 -> HITACHI
C8: Notes
B10: 1 | C10: The maximum CT lead length from the SWGR CT secondary terminal to relay terminals are considered as 150m
B12: 2 | C12: Size of the CT lead considered as 2.5 Sq. mm for calculation | Z12: 165m Lead Resistance of the current loop from the 33kV Incomer SWGR to 220kV Transformer Protection Panel.
B13: 3 | C13: The maximum VT lead length from the VT secondary terminal to relay terminals are considered as 150m
B14: 4 | C14: Size of the VT lead considered as 2.5 Sq. mm for calculation
B15: 5 | C15: Bus fault level is considered as 63kA for 400kV
B16: 6 | C16: X/R ratio is considered as 50 for 400kV system.
G53: Notes
G54: 1. CT Adequacy Check calculation of Remote End Cable Feeders are part of different submission
G55: 2. The CT sizing calculation is done for two type of relays RED670 and 7SD522 for cable feeders
G56: 3. Class X type CTs are proposed against that of Class TPS type CTs as per SOW
H62: Note:
G63: 1 | H63: This Calculation is Applicable for all the three S/S
G64: 2
H65: MV Max. Bus fault level/Switchgear Rating is assumed as 31.5kA as per Specification S-AAA-GEN-SFL (REV.0-2011) clause 3
H66: MV X/R Ratio is assumed as 15
H67: LV Max. Bus fault level/Switchgear Rating is assumed as 25kA as per Specification S-AAA-GEN-SFL (REV.0-2011) clause 3
H68: LV X/R Ratio is assumed as 15
H69: Power Cable Type is assumed as CU XLPE type .
H70: Positive Sequence Resistance, Positive Sequence Reactance , Zero Sequence Resistance and Zero Sequence Reactance of the power cable are assumed
H71: Route Length of the power cable is assumed as 5km
H72: Minimum 33kV Busbar Fault Current is Assumed as 20kA
H73: 33/11kV Transformer Impedance is Assumed to be 12%

Sheet CT-VT Data landscape
A1: HITACHI | H1: =Title!H1&" "&Title!H2 -> CT / VT ADEQUACY CHECK | T1: =Title!O1 -> Contract No. | W1: =Title!R1 -> N-19957.1-DF5W
T2: =Title!O2 -> Date | W2: =Title!R2 -> 46106
H3: =Title!H3 -> LT14 - LEWIS 400/132kV SUBSTATION | T3: =Title!O3 -> Document No. | W3: =Title!R3 -> -
T4: =Title!O4 -> Revision No. | W4: =Title!R4 -> A
A5: =Title!A5 -> Prep. By | C5: =Title!C5 -> AP | D5: =Title!D5 -> Checked By | G5: =Title!G5 -> RB | H5: Summary Sheet | T5: =Title!O5 -> Contractor | W5: =Title!R5 -> HITACHI
H7: CT parameters (Summary)
A8: 220/132kV Over All Transformer Differential (320MVA) Q08, Q13
A9: (Transformer Differential - 132kV side CT)
A10: CT / Core | D10: Ratio (A) | G10: CT Cable m/mm2 | I10: Class | K10: Rct @ 75OC (Ω) | M10: Rated Vk (V) | O10: Im @ Vk (mA) | Q10: Connected Devices | S10: CT Suitability | W10: Required Vk (V)
A11: ='[2]RET670_650-PX (LV)'!A398 -> BC1 | B11: ='[2]RET670_650-PX (LV)'!B398 -> Core1 | D11: ='[2]RET670_650-PX (LV)'!D398 -> 1500 | F11: ='[2]RET670_650-PX (LV)'!F398 -> 1 | G11: ='[2]RET670_650-PX (LV)'!G398 -> 50 | H11: ='[2]RET670_650-PX (LV)'!H398 -> 2.5 | I11: ='[2]RET670_650-PX (LV)'!I398 -> PX | K11: ='[2]RET670_650-PX (LV)'!K398 -> 3 | M11: ='[2]RET670_650-PX (LV)'!M398 -> 1500 | O11: ='[2]RET670_650-PX (LV)'!O398 -> 37.76 | Q11: ='[2]RET670_650-PX (LV)'!Q398 -> RET670 | S11: ='[2]RET670_650-PX (LV)'!S398 -> Suitably Dimensioned | W11: ='[2]RET670_650-PX (LV)'!H100 -> 94.143205
D12: ='[2]RET670_650-PX (LV)'!D399 -> - | K12: ='[2]RET670_650-PX (LV)'!K399 -> - | M12: ='[2]RET670_650-PX (LV)'!M399 -> - | O12: ='[2]RET670_650-PX (LV)'!O399 -> - | S12: - | W12: -
D13: ='[2]RET670_650-PX (LV)'!D400 -> - | K13: ='[2]RET670_650-PX (LV)'!K400 -> - | M13: ='[2]RET670_650-PX (LV)'!M400 -> - | O13: ='[2]RET670_650-PX (LV)'!O400 -> - | S13: ='[2]RET670_650-PX (LV)'!S400 -> - | W13: -
A14: (Transformer Differential - 220kV side CT)
A15: CT / Core | D15: Ratio (A) | G15: CT Cable m/mm2 | I15: Class | K15: Rct @ 75OC (Ω) | M15: Rated Vk (V) | O15: Im @ Vk (mA) | Q15: Connected Devices | S15: CT Suitability | W15: Required Vk (V)
A16: ='[2]RET670_650-PX (HV-T12) '!A398 -> T12 | B16: ='[2]RET670_650-PX (HV-T12) '!B398 -> Core1 | D16: ='[2]RET670_650-PX (HV-T12) '!D398 -> 1200 | F16: ='[2]RET670_650-PX (HV-T12) '!F398 -> 1 | G16: ='[2]RET670_650-PX (HV-T12) '!G398 -> 50 | H16: ='[2]RET670_650-PX (HV-T12) '!H398 -> 2.5 | I16: ='[2]RET670_650-PX (HV-T12) '!I398 -> PX | K16: ='[2]RET670_650-PX (HV-T12) '!K398 -> 5 | M16: ='[2]RET670_650-PX (HV-T12) '!M398 -> 1000 | O16: ='[2]RET670_650-PX (HV-T12) '!O398 -> 30 | Q16: ='[2]RET670_650-PX (HV-T12) '!Q398 -> RET670 | S16: ='[2]RET670_650-PX (HV-T12) '!S398 -> Suitably Dimensioned | W16: ='[2]RET670_650-PX (HV-T12) '!H100 -> 177.39685
D17: ='[2]RET670_650-PX (HV-T12) '!D399 -> - | K17: ='[2]RET670_650-PX (HV-T12) '!K399 -> - | M17: ='[2]RET670_650-PX (HV-T12) '!M399 -> - | O17: ='[2]RET670_650-PX (HV-T12) '!O399 -> - | S17: ='[2]RET670_650-PX (HV-T12) '!S399 -> - | W17: -
D18: ='[2]RET670_650-PX (HV-T12) '!D400 -> - | K18: ='[2]RET670_650-PX (HV-T12) '!K400 -> - | M18: ='[2]RET670_650-PX (HV-T12) '!M400 -> - | O18: ='[2]RET670_650-PX (HV-T12) '!O400 -> - | S18: ='[2]RET670_650-PX (HV-T12) '!S400 -> - | W18: -
A19: (OCEF Protection)
A20: CT / Core | D20: Ratio (A) | G20: CT Cable m/mm2 | I20: Class | K20: Rct @ 75OC (Ω) | M20: Rated Vk (V) | O20: Im @ Vk (mA) | Q20: Connected Devices | S20: CT Suitability | W20: Required Vk (V)
A21: ='[2]REF615 OC-5P (5)'!A141 -> BC1 | B21: ='[2]REF615 OC-5P (5)'!B141 -> Core3 | D21: ='[2]REF615 OC-5P (5)'!D141 -> 1500 | F21: ='[2]REF615 OC-5P (5)'!F141 -> 1 | G21: ='[2]REF615 OC-5P (5)'!G141 -> 50 | H21: ='[2]REF615 OC-5P (5)'!H141 -> 2.5 | I21: ='[2]REF615 OC-5P (5)'!I141 -> 5P | K21: ='[2]REF615 OC-5P (5)'!K141 -> 4 | M21: ='[2]REF615 OC-5P (5)'!M141 -> 30 | O21: ='[2]REF615 OC-5P (5)'!O141 -> - | Q21: ='[2]REF615 OC-5P (5)'!Q141 -> REF615+REF615 | S21: ='[2]REF615 OC-5P (5)'!S141 -> Suitably Dimensioned | W21: ='[2]REF615 OC-5P (5)'!G40 -> 26.666667
D22: ='[2]REF615 OC-5P (5)'!D142 -> - | K22: ='[2]REF615 OC-5P (5)'!K142 -> - | M22: ='[2]REF615 OC-5P (5)'!M142 -> - | O22: ='[2]REF615 OC-5P (5)'!O142 -> - | S22: ='[2]REF615 OC-5P (5)'!S142 -> - | W22: -
D23: ='[2]REF615 OC-5P (5)'!D143 -> - | K23: ='[2]REF615 OC-5P (5)'!K143 -> - | M23: ='[2]REF615 OC-5P (5)'!M143 -> - | O23: ='[2]REF615 OC-5P (5)'!O143 -> - | S23: ='[2]REF615 OC-5P (5)'!S143 -> - | W23: -
A24: (Low Imp. Busbar - 132kV side CT)
A25: CT / Core | D25: Ratio (A) | G25: CT Cable m/mm2 | I25: Class | K25: Rct @ 75OC (Ω) | M25: Rated Vk (V) | O25: Im @ Vk (mA) | Q25: Connected Devices | S25: CT Suitability | W25: Required Vk (V)
A26: ='[2]REB500-PX (5)'!A260 -> BC1 | B26: ='[2]REB500-PX (5)'!B260 -> Core5 | D26: ='[2]REB500-PX (5)'!D260 -> 3150 | F26: ='[2]REB500-PX (5)'!F260 -> 1 | G26: ='[2]REB500-PX (5)'!G260 -> 100 | H26: ='[2]REB500-PX (5)'!H260 -> 4 | I26: ='[2]REB500-PX (5)'!I260 -> PX | K26: ='[2]REB500-PX (5)'!K260 -> 10 | M26: ='[2]REB500-PX (5)'!M260 -> 3150 | O26: ='[2]REB500-PX (5)'!O260 -> 210.8 | Q26: ='[2]REB500-PX (5)'!Q260 -> REB500 | S26: ='[2]REB500-PX (5)'!S260 -> Suitably Dimensioned | W26: ='[2]REB500-PX (5)'!G148 -> 10
D27: ='[2]REB500-PX (5)'!D261 -> 1500 | K27: ='[2]REB500-PX (5)'!K261 -> 5 | M27: ='[2]REB500-PX (5)'!M261 -> 1000 | O27: ='[2]REB500-PX (5)'!O261 -> 147.73 | S27: ='[2]REB500-PX (5)'!S261 -> Suitably Dimensioned | W27: -
D28: ='[2]REB500-PX (5)'!D262 -> - | K28: ='[2]REB500-PX (5)'!K262 -> - | M28: ='[2]REB500-PX (5)'!M262 -> - | O28: ='[2]REB500-PX (5)'!O262 -> - | S28: ='[2]REB500-PX (5)'!S262 -> - | W28: -
A33: (Hi Imp. REF - 132kV Side CT)
A34: CT / Core | D34: Ratio (A) | G34: CT Cable m/mm2 | I34: Class | K34: Rct @ 75OC (Ω) | M34: Rated Vk (V) | O34: Im @ Vk (mA) | Q34: Connected Devices | S34: CT Suitability | W34: Required Vk (V)
A35: ='[2]RET615_Trafo LV REF (High)'!A91 -> BC1 | B35: ='[2]RET615_Trafo LV REF (High)'!B91 -> Core2 | D35: ='[2]RET615_Trafo LV REF (High)'!D91 -> 1500 | F35: ='[2]RET615_Trafo LV REF (High)'!F91 -> 1 | G35: ='[2]RET615_Trafo LV REF (High)'!G91 -> 50 | H35: ='[2]RET615_Trafo LV REF (High)'!H91 -> 2.5 | I35: ='[2]RET615_Trafo LV REF (High)'!I91 -> PX | K35: ='[2]RET615_Trafo LV REF (High)'!K91 -> 3 | M35: ='[2]RET615_Trafo LV REF (High)'!M91 -> 1500 | O35: ='[2]RET615_Trafo LV REF (High)'!O91 -> 74.39 | Q35: ='[2]RET615_Trafo LV REF (High)'!Q91 -> RET615 | S35: ='[2]RET615_Trafo LV REF (High)'!S91 -> Suitably Dimensioned | W35: ='[2]RET615_Trafo LV REF (High)'!G78 -> 308.19171
D36: ='[2]RET615_Trafo LV REF (High)'!D92 -> - | K36: ='[2]RET615_Trafo LV REF (High)'!K92 -> - | M36: ='[2]RET615_Trafo LV REF (High)'!M92 -> - | O36: ='[2]RET615_Trafo LV REF (High)'!O92 -> - | S36: ='[2]RET615_Trafo LV REF (High)'!S92 -> -
D37: ='[2]RET615_Trafo LV REF (High)'!D93 -> - | K37: ='[2]RET615_Trafo LV REF (High)'!K93 -> - | M37: ='[2]RET615_Trafo LV REF (High)'!M93 -> - | O37: ='[2]RET615_Trafo LV REF (High)'!O93 -> - | S37: ='[2]RET615_Trafo LV REF (High)'!S93 -> -
A38: ='[2]RET615_Trafo LV REF (High)'!A94 -> T2N | B38: ='[2]RET615_Trafo LV REF (High)'!B94 -> Core1 | D38: ='[2]RET615_Trafo LV REF (High)'!D94 -> 1500 | F38: ='[2]RET615_Trafo LV REF (High)'!F94 -> 1 | G38: ='[2]RET615_Trafo LV REF (High)'!G94 -> 50 | H38: ='[2]RET615_Trafo LV REF (High)'!H94 -> 2.5 | I38: ='[2]RET615_Trafo LV REF (High)'!I94 -> PX | K38: ='[2]RET615_Trafo LV REF (High)'!K94 -> 10 | M38: ='[2]RET615_Trafo LV REF (High)'!M94 -> 1500 | O38: ='[2]RET615_Trafo LV REF (High)'!O94 -> 100 | Q38: ='[2]RET615_Trafo LV REF (High)'!Q94 -> RET615 | S38: ='[2]RET615_Trafo LV REF (High)'!S94 -> Suitably Dimensioned | W38: ='[2]RET615_Trafo LV REF (High)'!G78 -> 308.19171
D39: ='[2]RET615_Trafo LV REF (High)'!D95 -> - | K39: ='[2]RET615_Trafo LV REF (High)'!K95 -> - | M39: ='[2]RET615_Trafo LV REF (High)'!M95 -> - | O39: ='[2]RET615_Trafo LV REF (High)'!O95 -> - | S39: ='[2]RET615_Trafo LV REF (High)'!S95 -> -
D40: ='[2]RET615_Trafo LV REF (High)'!D96 -> - | K40: ='[2]RET615_Trafo LV REF (High)'!K96 -> - | M40: ='[2]RET615_Trafo LV REF (High)'!M96 -> - | O40: ='[2]RET615_Trafo LV REF (High)'!O96 -> - | S40: ='[2]RET615_Trafo LV REF (High)'!S96 -> -
A41: ='[2]RET615_Trafo LV REF (High)'!A97 -> 0 | B41: ='[2]RET615_Trafo LV REF (High)'!B97 -> 0 | D41: ='[2]RET615_Trafo LV REF (High)'!D97 -> 1500 | F41: ='[2]RET615_Trafo LV REF (High)'!F97 -> 1 | G41: ='[2]RET615_Trafo LV REF (High)'!G97 -> 50 | H41: ='[2]RET615_Trafo LV REF (High)'!H97 -> 2.5 | I41: ='[2]RET615_Trafo LV REF (High)'!I97 -> PX | K41: ='[2]RET615_Trafo LV REF (High)'!K97 -> 3 | M41: ='[2]RET615_Trafo LV REF (High)'!M97 -> 1500 | O41: ='[2]RET615_Trafo LV REF (High)'!O97 -> 74.39 | Q41: ='[2]RET615_Trafo LV REF (High)'!Q97 -> RET615 | S41: ='[2]RET615_Trafo LV REF (High)'!S97 -> Suitably Dimensioned | W41: ='[2]RET615_Trafo LV REF (High)'!G78 -> 308.19171
D42: ='[2]RET615_Trafo LV REF (High)'!D98 -> - | K42: ='[2]RET615_Trafo LV REF (High)'!K98 -> - | M42: ='[2]RET615_Trafo LV REF (High)'!M98 -> - | O42: ='[2]RET615_Trafo LV REF (High)'!O98 -> - | S42: ='[2]RET615_Trafo LV REF (High)'!S98 -> -
D43: ='[2]RET615_Trafo LV REF (High)'!D99 -> - | K43: ='[2]RET615_Trafo LV REF (High)'!K99 -> - | M43: ='[2]RET615_Trafo LV REF (High)'!M99 -> - | O43: ='[2]RET615_Trafo LV REF (High)'!O99 -> - | S43: ='[2]RET615_Trafo LV REF (High)'!S99 -> -
A44: (BCU)
A45: CT / Core | D45: Ratio (A) | G45: CT Cable m/mm2 | I45: Class | K45: Rct @ 75OC (Ω) | M45: Rated Burden (VA) | Q45: Connected Devices | S45: CT Suitability
...

Sheet CT ADEQUACY
E22: CT ADEQUACY CHECK

Sheet CT-VT Burdens
H2: CT VT WIRING PARAMETERS CALCULATIONS
B8: For CT Wiring
B9: Burden of the connecting leads :
C10: Conductor cross section in mm2 | Q10: A | R10: = | S10: 6 | U10: mm2 | V10: **
C11: Resistance in W/km at 200 C | Q11: R20 | R11: = | S11: 3.69 | U11: Ω/km | X11: 7.41
C12: Specific resistance at 200 C | I12: (copper wires) | Q12: a | R12: = | S12: 0.00393 | U12: K-1
B14: Resistance in Ω/km at t0 C = | H14: R20 [ 1 + a ( t - 200 C ) ]
C15: Resistance in ohms/km at 750 C = | R15: = | S15: =S11*(1+S12*(75-20)) -> 4.4875935 | U15: Ω/km | X15: =S11*(1+S12*(75-20)) -> 4.4875935 | Z15: 5.61
C16: Resistance in ohms/m at 750 C = | Q16: R | R16: = | S16: =S15/1000 -> 0.0044875935 | U16: Ω/m
C17: Secondary current of CT | Q17: Is | R17: = | S17: 1 | U17: A
C18: Relay Rated current | Q18: Ir | R18: = | S18: 1 | U18: A
C19: Conductor length in meters ( CT to relay ) | Q19: l | R19: = | S19: 50 | U19: m | V19: **
C20: Lead Resistance from the CT to Relay | Q20: RL =R x l | R20: = | S20: =S16*S19 -> 0.22437968 | U20: Ω
C21: Lead Resistance of the current loop from the CT to Relay | Q21: 2RL = 2 x R x l | R21: = | S21: =2*S16*S19 -> 0.44875935 | U21: Ω | X21: =2*S16*S19 -> 0.44875935 | Z21: =2*S16*S19 -> 0.44875935
C22: VA consumption of the connecting leads | Q22: Pl = Is2 x Rl | R22: = | S22: =S17*S17*S21 -> 0.44875935 | U22: VA | X22: =S17*S17*S21 -> 0.44875935
C24: 165m Lead Resistance of the current loop from the 33kV Incomer SWGR to 220kV Transformer Protection Panel. | S24: =S16*165 -> 0.74045293 | U24: VA
B26: For VT Wiring
B27: Burden of the connecting leads :
C28: Conductor cross section in mm2 | Q28: A | R28: = | S28: 2.5 | U28: mm2 | V28: **
C29: Resistance in W/km at 200 C | Q29: R20 | R29: = | S29: 7.41 | U29: Ω/km
C30: Specific resistance at 200 C | I30: (copper wires) | Q30: a | R30: = | S30: 0.00393 | U30: K-1
B32: Resistance in Ω/km at t0 C = | I32: R20 [ 1 + a ( t - 200 C ) ]
C33: Resistance in W/km at 750 C = | R33: = | S33: =S29*(1+S30*(75-20)) -> 9.0116715 | U33: Ω/km
C34: Resistance in W/m at 750 C = | Q34: R | R34: = | S34: =S33/1000 -> 0.0090116715 | U34: Ω/m
C35: Primary Voltage of VT | Q35: Vp | R35: = | S35: 400 / √3 | U35: kV
C36: Secondary Voltage of VT | Q36: Vs | R36: = | S36: 0.11 / √3 | U36: kV
C37: Conductor length in meters ( VT to relay ) | Q37: l | R37: = | S37: 150 | U37: m | V37: **
C38: Lead Resistance from the VT to Relay | Q38: RL =R x l | R38: = | S38: =S34*S37 -> 1.3517507 | U38: Ω
C39: Lead Resistance of the current loop from the VT to Relay | Q39: 2RL = 2 x R x l | R39: = | S39: =2*S34*S37 -> 2.7035015 | U39: Ω
I44: ** | J44: Assumed
B47: CT/VT Burden of Connected Devices (per phase): | Q47: CT at 1A | S47: VT at 110V | W47: Note: Pl. refer the manual for CT/VT burden at different rated currents and voltages
C48: Relion 670/650 series Relays | O48: IED 670/650 | Q48: 0.02 | S48: 0.02 | U48: VA | X48: 150mVA for 5A | AB48: =0.15/5^2 -> 0.006
C49: Busbar Protection Relay | O49: REB500 | Q49: 0.01 | S49: 0.15 | U49: VA
C50: ABB REx 52x Relays | O50: REJ525/REJ521/REX521 | Q50: 0.1 | S50: 0.5 | U50: VA
C51: ABB Relion 650 series Relays | O51: IED650 | Q51: 0.02 | S51: 0.02 | U51: VA
C52: ABB SPACOM Relays | O52: SPAJ/SPAU/SPAF 1xxC series | Q52: 0.1 | S52: 0.5 | U52: VA
C53: ABB REx54x series Relays | O53: REF54x/RET54x | Q53: 0.02 | S53: 0.5 | U53: VA
C54: ABB Relion 630/620 series Relays | O54: IED630/620 | Q54: 0.02 | S54: 0.05 | U54: VA
C55: ABB Relion 615 series Relays | O55: IED615 | Q55: 0.02 | S55: 0.05 | U55: VA
C56: ABB REU523 Relay | O56: REU523 | Q56: - | S56: 0.1 | U56: VA
...

Sheet Parameters & Fault Cal. (4)
H2: System Parameters & Fault Current Cal.
B7: System Parameters:
C8: System Frequency | Q8: 50 | S8: Hz
C9: Bus Voltage Level | Q9: 33 | S9: kV
C10: Max. Bus fault level | Q10: 50 | S10: kA
C11: X/R Ratio | Q11: 15 | X11: As per Transco spec page 7/34
C12: MV Bus Voltage Level | Q12: 132 | S12: kV
C13: MV Max. Bus fault level/Switchgear Rating | Q13: 40 | S13: kA | X13: As pre SLD
C14: LV X/R Ratio
B16: Power line parameters:
A17: Assumed Cable: | E17: 3 | F17: C, | G17: CU | H17: HDPE, | J17: 240 | L17: mm2, | N17: 1 | O17: Cables/phase
B18: Cable Details
C20: Positive Sequence- Resistance | O20: R1 | P20: = | Q20: 0.223 | S20: Ω/Km
C21: Positive Sequence- Reactance | O21: X1 | P21: = | Q21: 0.18 | S21: Ω/Km
C22: Zero Sequence- Resistance | O22: R0 | P22: = | Q22: 0.15 | S22: Ω/Km
C23: Zero Sequence- Reactance | O23: X0 | P23: = | Q23: 0.08 | S23: Ω/Km
C24: Route length | P24: = | Q24: 1.2 | S24: km
C26: Cable +Ve seq. impedence | J26: Z1 | K26: = | L26: =Q20/N17 -> 0.223 | N26: + j | O26: =Q21/N17 -> 0.18 | Q26: Ω/Km
C27: Cable Zero seq. impedence | J27: Z0 | K27: = | L27: =Q22/N17 -> 0.15 | N27: + j | O27: =Q23/N17 -> 0.08 | Q27: Ω/Km
C28: Total cable +Ve seq. impedence | J28: Z1L | K28: = | L28: =L26*Q24 -> 0.2676 | N28: + j | O28: =O26*Q24 -> 0.216 | Q28: Ω
C29: Total cable Zero seq. impedence | J29: Z0L | K29: = | L29: =L27*Q24 -> 0.18 | N29: + j | O29: =O27*Q24 -> 0.096 | Q29: Ω
B31: Fault Current & Time Constant Calculations:
C32: Maximum HV Busbar fault current | P32: = | Q32: =Q10*1000 -> 50000 | S32: A
C33: HV rating of Busbar | P33: = | Q33: =Q9*1000 -> 33000 | S33: V
C34: Maximum MV Busbar fault current | P34: = | Q34: =Q13*1000 -> 40000 | S34: A
C35: MV rating of Busbar | P35: = | Q35: =Q12*1000 -> 132000 | S35: V
A37: For the above fault condition Source impedance (Zs), considering voltage | P37: = | Q37: 1 | S37: pu
E38: Zs | F38: = | G38: (V | H38: X | I38: =Q37 -> 1 | J38: ) / | K38: (√3 | L38: x | M38: I) | P38: = | Q38: =(Q33*Q37)/(SQRT(3)*Q32) -> 0.38105118 | S38: Ω
E39: Source X / R ratio | F39: = | G39: 2 | H39: x | I39: p | J39: x | K39: f | L39: x | M39: (L/R)
E40: System X/R Ratio | L40: X/R | P40: = | Q40: =Q11 -> 15
E41: System Frequency | L41: f | P41: = | Q41: =Q8 -> 50
C42: Now, | E42: Impedence Angle | L42: øs = | M42: Tan-1(X/R)
E43: Impedence Angle in radians | L43: øs | P43: = | Q43: =ATAN(Q40) -> 1.5042282
E44: Impedence Angle in Degrees | L44: øs | P44: = | Q44: =DEGREES(Q43) -> 86.185925
E46: System Resistance | K46: Rs | L46: =Zs x Cos øs | P46: = | Q46: =Q38*COS(Q43) -> 0.025347147 | S46: W
E47: System Reactance | K47: Xs | L47: =Zs x Sin øs | P47: = | Q47: =Q38*SIN(Q43) -> 0.38020721 | S47: W
C48: Hence, | E48: Source Impedence | K48: Zs | L48: = | N48: =Q46 -> 0.025347147 | P48: + j | Q48: =Q47 -> 0.38020721 | S48: W
A49: Source Impedance Ratio (SIR)
C50: SIR | D50: = | E50: Zs | F50: / | G50: (80% * Z1L) | L50: where, | N50: Z1L | O50: = | P50: =SQRT(L28^2+O28^2) -> 0.34389789 | R50: ohm
D51: = | E51: =Q38 -> 0.38105118 | G51: / | H51: ( 0.8 * | J51: =P50 -> 0.34389789 | L51: )
...

Sheet BAY1
E22: Bus section coupler (BC1 - 13, 01,00, 10)

Sheet BUP BCU
A1: HITACHI | H1: =Title!H1 -> CT / VT | O1: =Title!O1 -> Contract No. | R1: =Title!R1 -> N-19957.1-DF5W
H2: =Title!H2 -> ADEQUACY CHECK | O2: =Title!O2 -> Date | R2: =Title!R2 -> 46106
H3: =Title!H3 -> LT14 - LEWIS 400/132kV SUBSTATION | O3: =Title!O3 -> Document No. | R3: =Title!R3 -> -
O4: =Title!O4 -> Revision No. | R4: =Title!R4 -> A
A5: =Title!A5 -> Prep. By | C5: =Title!C5 -> AP | D5: =Title!D5 -> Checked By | G5: =Title!G5 -> RB | H5: BUS SECTION COUPLER | O5: =Title!O5 -> Contractor | R5: =Title!R5 -> HITACHI
B7: T1 | D7: Core1 | H7: (OC+BCPU+FMS) | S7: Connected devices: | T7: REC670
T8: REF650
H9: Tap-1 | J9: Tap-2 | L9: Tap-3
B10: CT Ratio: | H10: 2500 | J10: - | L10: - | N10: / | O10: 1 | P10: A
B11: Class of Accuracy: | H11: 5P20
B12: CT Resistance: | G12: Rct< | H12: 5 | J12: W
B13: Knee Point Voltage: | G13: Vk> | H13: 750 | J13: V | W13: =#REF! -> #REF!
B14: Magnetizing Current: | G14: I0< | H14: 50 | J14: mA at Vk
A16: Other Burdens on same CT core:
B18: Burden of | D18: =T7 -> REC670 | I18: = | J18: ='CT-VT Burdens'!Q48 -> 0.02 | L18: VA | N18: CT internal Burden
B19: Burden of | D19: =T8 -> REF650 | I19: = | J19: ='CT-VT Burdens'!Q48 -> 0.02 | L19: VA | N19: PE | O19: = | P19: In | Q19: x | R19: In | S19: x | T19: Rct
B20: Burden of | D20: =T9 -> 0 | I20: = | L20: VA | O20: = | P20: =O10 -> 1 | Q20: x | R20: =O10 -> 1 | S20: x | T20: =H12 -> 5
B21: Total lead burden | I21: = | J21: ='CT-VT Burdens'!S22 -> 0.44875935 | L21: VA | O21: = | P21: =P20*R20*T20 -> 5 | R21: VA
B22: Total lead + other burden | H22: PL | I22: = | J22: =SUM(J18:J21) -> 0.48875935 | L22: VA
B24: Non-directional instantaneous and definitive time, phase and residual overcurrent protection
B25: Ealreq = | E25: 1.5 | F25: x | G25: Iop | H25: Isr | J25: x | K25: ( | L25: Rct | M25: + | N25: Rl | O25: + | P25: Sr | S25: ) | T25: ---(1)
H26: Ipr | P26: Ir | Q26: x | R26: Ir
C28: 6 times rated primary current concidered
C29: The primary operate value (A) | Q29: Iop | R29: = | S29: =6*S30 -> 15000 | U29: A
C30: The rated primary CT current (A) | Q30: Ipr | R30: = | S30: =H10 -> 2500 | U30: A
C31: The rated secondary CT current (A) | Q31: Isr | R31: = | S31: =O10 -> 1 | U31: A
C32: The rated current of the protection IED (A) | Q32: Ir | R32: = | S32: =O10 -> 1 | U32: A
C33: The secondary resistance of the CT (ohm) | Q33: Rct | R33: = | S33: =H12 -> 5 | U33: ohm
C34: The resistance of the secondary cable and additional load (ohm). | Q34: RL | R34: = | S34: =J22 -> 0.48875935 | U34: ohm
C35: The burden of an IED current input channel (VA) | Q35: SR | R35: = | S35: =J18 -> 0.02 | U35: VA
B37: Ealreq = | D37: 1.5 | E37: x | F37: =S29 -> 15000 | H37: x | I37: =S31 -> 1 | K37: x | L37: ( | M37: =S33 -> 5 | N37: + | O37: =S34 -> 0.48875935 | P37: + | Q37: =S35 -> 0.02 | T37: )
I38: =S30 -> 2500 | Q38: =S32 -> 1 | R38: x | S38: =S32 -> 1
C40: = | D40: =ROUNDUP(D37*F37*(I37/I38)*(M37+O37+(Q37/(Q38*S38))),2) -> 49.58 | F40: V
B49: Non-directional inverse time delayed phase and residual overcurrentprotection
B51: Ealreq = | E51: 20 | F51: x | G51: Iop | H51: Isr | J51: x | K51: ( | L51: Rct | M51: + | N51: Rl | O51: + | P51: Sr | S51: ) | T51: ---(1)
H52: Ipr | P52: Ir | Q52: x | R52: Ir
C54: 1.2 times rated primary current concidered
C55: The primary operate value (A) | Q55: Iop | R55: = | S55: =1.2*S56 -> 3000 | U55: A
C56: The rated primary CT current (A) | Q56: Ipr | R56: = | S56: =H10 -> 2500 | U56: A
C57: The rated secondary CT current (A) | Q57: Isr | R57: = | S57: =O10 -> 1 | U57: A
...

Sheet BUP BCU(1)
A1: HITACHI | H1: =[3]Title!H1 -> CT / VT | O1: =Title!O1 -> Contract No. | R1: =Title!R1 -> N-19957.1-DF5W
H2: =[3]Title!H2 -> ADEQUACY CHECK | O2: =Title!O2 -> Date | R2: =Title!R2 -> 46106
H3: =Title!H3 -> LT14 - LEWIS 400/132kV SUBSTATION | O3: =Title!O3 -> Document No. | R3: =Title!R3 -> -
O4: =Title!O4 -> Revision No. | R4: =Title!R4 -> A
A5: =[3]Title!A5 -> Prep. By | C5: =[3]Title!C5 -> AK | D5: =Title!D5 -> Checked By | G5: =[3]Title!G5 -> LN | H5: BUS SECTION COUPLER | O5: =Title!O5 -> Contractor | R5: =[3]Title!R5 -> HITACHI ENERGY
B7: T1 | D7: Core1 | S7: Connected devices: | T7: REF650
T8: REC670
H9: Tap-1 | J9: Tap-2 | L9: Tap-3
B10: CT Ratio: | H10: 2500 | J10: - | L10: - | N10: / | O10: 1 | P10: A
B11: Class of Accuracy: | H11: 5P20
B12: CT Resistance: | G12: Rct< | H12: 5 | J12: W
B13: Knee Point Voltage: | G13: Vk> | J13: V | W13: =G61 -> Suitably Dimentioned
B14: Magnetizing Current: | G14: I0< | J14: mA at Vk
A16: Other Burdens on same CT core:
B18: Burden of | D18: =T7 -> REF650 | I18: = | J18: ='CT-VT Burdens'!Q48 -> 0.02 | L18: VA | N18: CT internal Burden
B19: Burden of | D19: =T8 -> REC670 | I19: = | J19: ='CT-VT Burdens'!Q48 -> 0.02 | L19: VA
B20: Burden of | D20: =T9 -> 0 | I20: = | L20: VA | N20: PE | O20: = | P20: In | Q20: x | R20: In | S20: x | T20: Rct
B21: Total lead burden | I21: = | J21: ='CT-VT Burdens'!S22 -> 0.44875935 | L21: VA | O21: = | P21: =O10 -> 1 | Q21: x | R21: =O10 -> 1 | S21: x | T21: =H12 -> 5
B22: Total lead + other burden | H22: PL | I22: = | J22: =SUM(J18:J21) -> 0.48875935 | L22: VA | O22: = | P22: =P21*R21*T21 -> 5 | R22: VA
A24: The design values according to BS can be approximately transferred in to IEC60044 Standard using the following formula: | W24: The design values according to BS can be approximately transferred in to IEC60044 Standard using the following formula:
C27: Vk | D27: = | E27: ( ( | F27: PN | G27: + | H27: PE | I27: ) x | J27: n | K27: ) / ( | L27: In | M27: x | N27: 1.3 | O27: )
A28: Or
C29: PN | D29: = | E29: ( ( | F29: 1.3 | G29: x | H29: Vk | J29: x | K29: In | L29: ) / | M29: n | N29: ) - | O29: PE
C31: Max through fault current at close in fault | Q31: Itkmax | R31: = | S31: ='Parameters & Fault Cal. (4)'!Q32 -> 50000 | U31: A
C32: CT Primary Current, | Q32: Ipn | R32: = | S32: =H10 -> 2500 | U32: A
C33: Rated Knee Point Voltage, | Q33: Vk | R33: = | S33: =H13 -> 0 | U33: V
C34: Internal Burden, | Q34: PE | R34: = | S34: =P22 -> 5 | U34: VA
C35: Burden of CT Leads and burden of connected devices | Q35: PL | R35: = | S35: =J22 -> 0.48875935 | U35: VA
C36: Rated Secondary Current, | Q36: In | R36: = | S36: =O10 -> 1 | U36: A
C37: CT Accuracy Limiting Factor | Q37: n | R37: = | S37: 20
C38: Rated CT Burden | Q38: PN | R38: = | S38: 30
C45: PN | D45: = | E45: ( ( | F45: 1.3 | G45: x | H45: Vk | J45: x | K45: In | L45: ) / | M45: n | N45: ) - | O45: PE
D46: = | E46: ( ( | F46: 1.3 | G46: x | H46: =S33 -> 0 | J46: x | K46: =S36 -> 1 | L46: ) / | M46: =S37 -> 20 | N46: ) - | O46: =S34 -> 5
D47: = | E47: =((F46*H46)/(K46*M46))-O46 -> -5 | G47: VA
E51: Required Kssc' | F51: = | G51: Itkmax | I51: / | J51: Ipn
F52: = | G52: =S31 -> 50000 | I52: / | J52: =S32 -> 2500
F53: = | G53: =G52/J52 -> 20
E55: Available (effective) Kssc' | F55: = | G55: n | H55: x ( ( | I55: PE | J55: + | K55: PN | L55: ) / ( | M55: PE | N55: + | O55: PL | P55: )
F56: = | G56: =S37 -> 20 | H56: x ( ( | I56: =S34 -> 5 | J56: + | K56: =S38 -> 30 | L56: ) / ( | M56: =S34 -> 5 | N56: + | O56: =S35 -> 0.48875935 | P56: )
F57: = | G57: =G56*((I56+K56)/(M56+O56)) -> 127.53337
...

Sheet BBP P743(1)
A1: HITACHI | H1: =[4]Title!H1 -> CT / VT | O1: =[4]Title!O1 -> Contract No. | R1: =Title!R1 -> N-19957.1-DF5W
H2: =[4]Title!H2 -> ADEQUACY CHECK | O2: =[4]Title!O2 -> Date | R2: =Title!R2 -> 46106
H3: =Title!H3 -> LT14 - LEWIS 400/132kV SUBSTATION | O3: =[4]Title!O3 -> Document No. | R3: =Title!R3 -> -
O4: =[4]Title!O4 -> Revision No. | R4: =Title!R4 -> A
A5: =[4]Title!A5 -> Prep. By | C5: =[4]Title!C5 -> AP | D5: =[4]Title!D5 -> Checked By | G5: =[4]Title!G5 -> RB | H5: BUS SECTION COUPLER | O5: =[4]Title!O5 -> Contractor | R5: =Title!R5 -> HITACHI
B7: T1 | D7: Core2 | S7: Connected devices: | T7: P743
H9: Tap-1 | J9: Tap-2 | L9: Tap-3
B10: CT Ratio: | H10: 2500 | J10: - | L10: - | N10: / | O10: 1 | P10: A
B11: Class of Accuracy: | H11: PX-B
B12: CT Resistance: | G12: Rct< | H12: 5 | J12: W
B13: Knee Point Voltage: | G13: Vk> | H13: 750 | J13: V | W13: =H59 -> Suitably Dimentioned
B14: Magnetizing Current: | G14: I0< | H14: 60 | J14: mA at Vk
A16: Other Burdens on same CT core:
B18: Burden of | D18: =T7 -> P743 | I18: = | J18: ='CT-VT Burdens'!Q98 -> 0.1 | L18: VA
B19: Burden of | D19: =T8 -> 0 | I19: = | L19: VA
B20: Burden of | D20: =T9 -> 0 | I20: = | L20: VA
B21: Total lead burden | I21: = | J21: ='CT-VT Burdens'!S22 -> 0.44875935 | L21: VA
B22: Total lead + other burden | H22: PL | I22: = | J22: =SUM(J18:J21) -> 0.54875935 | L22: VA
C24: Max primary fault current (same for all feeders) | Q24: IFmax | R24: = | S24: ='Parameters & Fault Cal. (4)'!Q10 *1000 -> 50000 | U24: A
C25: CT Primary Current | Q25: Ipn | R25: = | S25: =H10 -> 2500 | U25: A
C26: Max secondary fault current (same for all feeders) | Q26: Ifmax | R26: = | S26: =S24/S25*O10 -> 20 | U26: A
C27: Resistive burden of CT Leads (2Rl) and other connected devices | Q27: Rb' | R27: = | S27: =J22/O10*O10 -> 0.54875935 | U27: W
C28: Max primary contribution from a feeder to an internal fault | Q28: IFmax int | R28: = | S28: =20*S25 -> 50000 | U28: A
C29: Max secondary contribution from a feeder to an internal fault | Q29: Ifmax int | R29: = | S29: =S28/S25 -> 20 | U29: A
A31: The CT requirement is as follows:
A33: Criteria I
B35: Vk | D35: >= | E35: 0.5 | F35: x | G35: Ifmax | I35: x ( | J35: Rct | L35: + | M35: Rb' | O35: )
D36: = | E36: 0.5 | F36: x | G36: =S26 -> 20 | I36: x ( | J36: =H12 -> 5 | L36: + | M36: =S27 -> 0.54875935 | O36: )
D37: = | E37: =E36*G36*(J36+M36) -> 55.487594
A39: Criteria II
B41: Vk | D41: >= | E41: Ifmax int | G41: x ( | H41: Rct | J41: + | K41: Rb' | M41: )
D42: = | E42: =S29 -> 20 | G42: x ( | H42: =H12 -> 5 | J42: + | K42: =S27 -> 0.54875935 | M42: )
D43: = | E43: =E42*(H42+K42) -> 110.97519
A48: Adequacy Check
B50: Criteria I
F51: Available Vk | G51: =IF(E52>H52, ">","<") -> > | H51: Required Vk | L51: (Criteria I)
E52: =H13 -> 750 | G52: =G51 -> > | H52: =E37 -> 55.487594
F53: Hence: | H53: Criteria I | J53: is | K53: =IF(G52=">", "Satisfied", "Not Satisfied") -> Satisfied
B54: Criteria II
F55: Available Vk | G55: =IF(E56>H56, ">","<") -> > | H55: Required Vk | L55: (Criteria II)
...

Sheet BBP FU1 - REB500
A1: HITACHI | H1: =Title!H1 -> CT / VT | O1: =Title!O1 -> Contract No. | R1: =Title!R1 -> N-19957.1-DF5W
H2: =Title!H2 -> ADEQUACY CHECK | O2: =Title!O2 -> Date | R2: =Title!R2 -> 46106
H3: =Title!H3 -> LT14 - LEWIS 400/132kV SUBSTATION | O3: =Title!O3 -> Document No. | R3: =Title!R3 -> -
O4: =Title!O4 -> Revision No. | R4: =Title!R4 -> A
A5: =Title!A5 -> Prep. By | C5: =Title!C5 -> AP | D5: =Title!D5 -> Checked By | G5: =Title!G5 -> RB | H5: BUS SECTION COUPLER | O5: =Title!O5 -> Contractor | R5: =Title!R5 -> HITACHI
B7: T1 | D7: Core3 | H7: (Low Imp. Busbar) | S7: Connected devices: | T7: REB500
H9: Tap-1 | J9: Tap-2 | L9: Tap-3
B10: CT Ratio: | H10: 2500 | J10: - | L10: - | N10: / | O10: 1 | P10: A
B11: Class of Accuracy: | H11: PX - B
B12: CT Resistance: | G12: Rct< | H12: 5 | J12: W
B13: Knee Point Voltage: | G13: Vk> | H13: 750 | J13: V | W13: =#REF! -> #REF!
B14: Magnetizing Current: | G14: I0< | H14: 60 | J14: mA at Vk
A16: Other Burdens on same CT core:
B18: Burden of | D18: =T7 -> REB500 | I18: = | J18: ='CT-VT Burdens'!Q49 -> 0.01 | L18: VA | N18: CT internal Burden
B19: Burden of | D19: =T8 -> 0 | I19: = | L19: VA | N19: PE | O19: = | P19: In | Q19: x | R19: In | S19: x | T19: Rct
B20: Burden of | D20: =T9 -> 0 | I20: = | L20: VA | O20: = | P20: =O10 -> 1 | Q20: x | R20: =O10 -> 1 | S20: x | T20: =H12 -> 5
B21: Total lead burden | I21: = | J21: ='CT-VT Burdens'!S22 -> 0.44875935 | L21: VA | O21: = | P21: =P20*R20*T20 -> 5 | R21: VA
B22: Total lead + other burden | H22: PL | I22: = | J22: =SUM(J18:J21) -> 0.45875935 | L22: VA
B24: CT-Requirements for BB Protection
C25: Maximum Primary Fault Current | Q25: Isc | R25: = | S25: ='Parameters & Fault Cal. (4)'!Q10 *1000 -> 50000 | U25: A
C26: CT Primary Current, | Q26: Ipn | R26: = | S26: =H10 -> 2500 | U26: A
C27: Rated Voltage | Q27: UN2 | R27: = | S27: 400 | U27: kV
C28: Rated Knee Point Voltage, | Q28: Vk | R28: = | S28: =H13 -> 750 | U28: V
C29: Internal Resistance CT | Q29: Rct | R29: = | S29: =P21 -> 5 | U29: VA
C30: Conn. Lead + Relay Burden | Q30: RL | R30: = | S30: =J22 -> 0.45875935 | U30: VA
C31: Rated Secondary Current, | Q31: Isc | R31: = | S31: =O10 -> 1 | U31: A
C32: Nominal Frequency of the network | Q32: fn | R32: = | S32: 50
C34: Required OC factor condition. 1:
D35: At Max. Through fault current CT’s shall not saturate for currents below 5 times rated current.
I36: n' | J36: = | K36: Isc
K37: 5 * Ipn
C38: Required OC factor Condition 2:
D39: n2' >= 10 for TN <=120 msec
D40: n2' >= 20 for 120ms <= TN <=300 ms
B41: Where, | D41: n' = Required OC factor
D42: Isc = max. bus fault current
D43: Ipn = Rated primary current (A)
AB45: ** | AC45: Rated Bus fault current
B48: Required OC factor condition 1:
C50: n'(1) | D50: = | E50: =S25 -> 50000
...

Sheet IFP1-RED670
H3: RED670 TEMPLATE.
A5: Here We have placed the calculations CT Adequacy Check of Two tapping for RED 670
B7: T1 | D7: Core1 | H7: (Diff. + Dist.) | S7: Connected devices: | T7: RED670 | W7: Note: CT requirements for other protection functions are different. Pl. refer to Application Manual
H9: Tap-1 | J9: Tap-2 | L9: Tap-3
B10: CT Ratio: | H10: 1600 | J10: 1800 | L10: - | N10: / | O10: 1 | P10: A
B11: Class of Accuracy: | H11: PX-A
B12: CT Resistance: | G12: Rct < | H12: 12 | J12: W
B13: Knee Point Voltage: | G13: Vk > | H13: 3500 | J13: V | W13: Highest Vk required = | AB13: =Q120 -> 632.78933
B14: Magnetizing Current: | G14: I0< | H14: 40 | J14: mA at Vk
A16: Other Burdens on same CT core:
B18: Burden of | D18: =T7 -> RED670 | H18: Sr' | I18: = | J18: ='CT-VT Burdens'!Q48 -> 0.02 | L18: VA | N18: Lead + Other resisitance connected
B19: Burden of | D19: =T8 -> 0 | I19: = | L19: VA | N19: Rl | O19: = | P19: Sl | Q19: / ( | R19: Isn | S19: x | T19: Isn | U19: )
B20: Burden of | I20: = | L20: VA | O20: = | P20: =J22 -> 0.46875935 | Q20: / ( | R20: =O10 -> 1 | S20: x | T20: =O10 -> 1 | U20: )
B21: Total lead burden | I21: = | J21: ='CT-VT Burdens'!S22 -> 0.44875935 | L21: VA | O21: = | P21: =P20/(R20*T20) -> 0.46875935 | R21: W
B22: Total lead + other burden | H22: Sl | I22: = | J22: =SUM(J18:K21) -> 0.46875935 | L22: VA
A24: A. CT ADEQUECY CHECK FOR DIFFERENTIAL FUNCTION:
A25: The CT secondary limiting e.m.f (Eal) should meet the following requirements as per Relay manufacturer.
A27: For Close-in faults:
A28: Ealreq = | F28: Ikmax | H28: x | I28: Isn | K28: x | L28: ( | M28: Rct | N28: + | O28: Rl | P28: + | Q28: Sr | T28: ) | U28: ---(1)
I29: Ipn | Q29: Ir | R29: x | S29: Ir
A30: For Through faults:
A31: Ealreq = | D31: 2 | E31: x | F31: Itmax | H31: x | I31: Isn | K31: x | L31: ( | M31: Rct | N31: + | O31: Rl | P31: + | Q31: Sr | T31: ) | U31: ---(2)
I32: Ipn | Q32: Ir | R32: x | S32: Ir
B34: Equivalent Secondary emf. Required | P34: Ealreq
B35: CT primary rated current(A) | P35: Ipn | Q35: = | R35: =H10 -> 1600 | T35: A
B36: Max. primary fundamental frequency fault current for close-in faults | P36: Ikmax | Q36: = | R36: ='Parameters & Fault Cal. (4)'!Q32 -> 50000 | T36: A
B37: Max. primary fundamental frequency fault current for through fault | P37: Itmax | Q37: = | R37: ='Parameters & Fault Cal. (4)'!M70 -> 28681.091 | T37: A | U37: 3-phase
Q38: = | R38: ='Parameters & Fault Cal. (4)'!M91 -> 30950.978 | T38: A | U38: 1-phase
B39: CT secondary rated current | P39: Isn | Q39: = | R39: ='CT-VT Burdens'!S17 -> 1 | T39: A
B40: Relay rated current | P40: Ir | Q40: = | R40: ='CT-VT Burdens'!S18 -> 1 | T40: A
B41: CT secondary winding resistance. | P41: Rct | Q41: = | R41: =H12 -> 12 | T41: W
B42: Lead Resistance of the current loop from the CT to Relay | P42: Rl | Q42: = | R42: =P21 -> 0.46875935 | T42: W
B43: Burden of RED 670 Relay | P43: Sr | Q43: = | R43: =J18 -> 0.02 | T43: VA
A46: For Close-in faults:
A47: Ealreq = | F47: =R36 -> 50000 | H47: x | I47: =R39 -> 1 | K47: x | L47: ( | M47: =R41 -> 12 | N47: + | O47: =R42 -> 0.46875935 | P47: + | Q47: =R43 -> 0.02 | T47: ) | U47: ---(1)
I48: =R35 -> 1600 | Q48: =R40 -> 1 | R48: x | S48: =R40 -> 1
C50: = | D50: =F47*(I47/I48)*(M47+O47+(Q47/(Q48*S48))) -> 390.27373 | F50: V
A52: For Through faults (3-ph):
A53: Ealreq = | D53: 2 | E53: x | F53: =R37 -> 28681.091 | H53: x | I53: =R39 -> 1 | K53: x | L53: ( | M53: =R41 -> 12 | N53: + | O53: =R42 -> 0.46875935 | P53: + | Q53: =Q47 -> 0.02 | T53: ) | U53: ---(2)
I54: =R35 -> 1600 | Q54: =R40 -> 1 | R54: x | S54: =R40 -> 1
...

Sheet BCU+OC-5P SEL751+7SJ85 (2)
H3: 7SJ85
B7: T1 | D7: Core2 | H7: (OC +BCU) | S7: Connected devices: | T7: 7SJ85
H9: Tap-1 | J9: Tap-2 | L9: Tap-3
B10: CT Ratio: | H10: 1000 | J10: 600 | L10: - | N10: / | O10: 1 | P10: A
B11: Class of Accuracy: | H11: 5P | I11: 20
B12: CT Resistance: | G12: Rct< | H12: 14 | J12: W
B13: Rated Burden | G13: PN | H13: 13 | J13: VA | W13: =G42 -> Under Dimensioned | AC13: 5
A15: Other Burdens on same CT core:
B17: Burden of | D17: =T7 -> 7SJ85 | I17: = | J17: ='CT-VT Burdens'!Q54 -> 0.02 | L17: VA | N17: CT internal Burden
B18: Burden of | D18: =T8 -> 0 | I18: = | L18: VA
B19: Burden of | D19: =T9 -> 0 | I19: = | L19: VA
B20: Burden of | L20: VA | N20: PE | O20: = | P20: In | Q20: x | R20: In | S20: x | T20: Rct
B21: Total lead burden | I21: = | J21: ='CT-VT Burdens'!S22 -> 0.44875935 | L21: VA | O21: = | P21: =O10 -> 1 | Q21: x | R21: =O10 -> 1 | S21: x | T21: =H12 -> 14
B22: Total lead + other burden | H22: PL | I22: = | J22: =SUM(J17:J21) -> 0.46875935 | L22: VA | O22: = | P22: =P21*R21*T21 -> 14 | R22: VA
C24: Max through fault current at close in fault | Q24: Itkmax | R24: = | S24: ='Parameters & Fault Cal. (4)'!Q10*1000 -> 50000 | U24: A | V24: ** | X24: This Current Must be Linked Later to Fault Setting
C25: CT Primary Current, | Q25: Ipn | R25: = | S25: =H10 -> 1000 | U25: A
C26: Internal Burden, | Q26: PE | R26: = | S26: =P22 -> 14 | U26: VA
C27: Burden of CT Leads and burden of connected devices | Q27: PL | R27: = | S27: =J22 -> 0.46875935 | U27: VA
C28: Rated Secondary Current, | Q28: In | R28: = | S28: =O10 -> 1 | U28: A
C29: CT Accuracy Limiting Factor | Q29: n | R29: = | S29: =I11 -> 20
C30: CT Burden | Q30: PN | R30: = | S30: =H13 -> 13 | U30: VA
E32: Required Kssc' | F32: = | G32: Itkmax | I32: / | J32: Ipn
F33: = | G33: =S24 -> 50000 | I33: / | J33: =S25 -> 1000
F34: = | G34: =G33/J33 -> 50
E36: Available (effective) Kssc' | F36: = | G36: n | H36: x ( ( | I36: PE | J36: + | K36: PN | L36: ) / ( | M36: PE | N36: + | O36: PL | P36: )
F37: = | G37: =S29 -> 20 | H37: x ( ( | I37: =S26 -> 14 | J37: + | K37: =S30 -> 13 | L37: ) / ( | M37: =S26 -> 14 | N37: + | O37: =S27 -> 0.46875935 | P37: )
F38: = | G38: =G37*((I37+K37)/(M37+O37)) -> 37.32179
E40: Available Kssc' | F40: =IF(D41>G41,">","<") -> < | G40: Required Kssc'
D41: =G38 -> 37.32179 | F41: =F40 -> < | G41: =G34 -> 50
E42: Hence CT is: | G42: =IF(F40=">","Suitably Dimensioned","Under Dimensioned") -> Under Dimensioned
J45: ** Assumed
B48: =B7 -> T1 | D48: =D7 -> Core2 | H48: =H7 -> (OC +BCU) | S48: Connected devices: | T48: =T7 -> 7SJ85
B49: =B8 -> 0 | T49: =T8 -> 0
H50: Tap-1 | J50: Tap-2 | L50: Tap-3 | T50: =T9 -> 0
B51: CT Ratio: | H51: =H10 -> 1000 | J51: =J10 -> 600 | L51: =L10 -> - | N51: / | O51: =O10 -> 1 | P51: A | T51: =T10 -> 0
B52: Class of Accuracy: | J52: =H11 -> 5P | K52: =I11 -> 20
B53: CT Resistance: | I53: Rct< | J53: 10 | L53: W
B54: Rated Burden | I54: PN | J54: 12 | L54: VA | W54: =G83 -> Under Dimentioned | AD54: 5
A56: Other Burdens on same CT core:
B58: Burden of | D58: =T48 -> 7SJ85 | I58: = | J58: =J17 -> 0.02 | L58: VA | N58: CT internal Burden
...

Sheet Tariff Check-0.2FS  (3)
A1: HITACHI | H1: =Title!H1 -> CT / VT | O1: =Title!O1 -> Contract No. | R1: =Title!R1 -> N-19957.1-DF5W
H2: =Title!H2 -> ADEQUACY CHECK | O2: =Title!O2 -> Date | R2: =Title!R2 -> 46106
H3: =Title!H3 -> LT14 - LEWIS 400/132kV SUBSTATION | O3: =Title!O3 -> Document No. | R3: =Title!R3 -> -
O4: =Title!O4 -> Revision No. | R4: =Title!R4 -> A
A5: =Title!A5 -> Prep. By | C5: =Title!C5 -> AP | D5: =Title!D5 -> Checked By | G5: =Title!G5 -> RB | H5: 33kV DIAMOND CABLE FEEDERS | O5: =Title!O5 -> Contractor | R5: =Title!R5 -> HITACHI
B7: T1 | D7: Core4 | H7: (Tariff Meter- Check) | S7: Connected devices: | T7: XC-RACK
T8: GOSSEN
H9: Tap-1 | J9: Tap-2 | L9: Tap-3
B10: CT Ratio: | H10: 600 | J10: 200 | L10: - | N10: / | O10: 1 | P10: A
B11: Class of Accuracy: | H11: 0.2FS10
B12: CT Resistance: | G12: Rct< | H12: 8 | J12: W
B13: Factor of Safety | G13: FS | H13: 10 | W13: =J47 -> Suitable Dimensions
B14: Rated Burden | G14: PN | H14: 7.5 | J14: VA
A16: Other Burdens on same CT core:
B18: Burden of | D18: =T7 -> XC-RACK | I18: = | J18: ='CT-VT Burdens'!Q85 -> 0.008 | L18: VA | N18: CT internal Burden | AC18: rec670 | AE18: 100A for 1 S
B19: Burden of | D19: =T8 -> GOSSEN | I19: = | J19: ='CT-VT Burdens'!Q86 -> 0.25 | L19: VA
B20: Burden of | D20: =T9 -> 0 | I20: = | L20: VA | N20: PE | O20: = | P20: In | Q20: x | R20: In | S20: x | T20: Rct
B21: Burden of | D21: =T10 -> 0 | I21: = | L21: VA | O21: = | P21: =O10 -> 1 | Q21: x | R21: =O10 -> 1 | S21: x | T21: =H12 -> 8
B22: Total lead burden | I22: = | J22: ='CT-VT Burdens'!S22 -> 0.44875935 | L22: VA | O22: = | P22: =P21*R21*T21 -> 8 | R22: VA
B23: Total lead + other burden | H23: PL | I23: = | J23: =SUM(J18:K22) -> 0.70675935 | L23: VA
B25: CT Primary Current, | N25: Ipn | O25: = | P25: =H10 -> 600 | R25: A
B26: Internal Burden, | N26: PE | O26: = | P26: =H12 -> 8 | R26: VA
B27: Burden of CT Leads and burden of connected devices | N27: PL | O27: = | P27: =J23 -> 0.70675935 | R27: VA
B28: Rated Secondary Current, | N28: In | O28: = | P28: =O10 -> 1 | R28: A
B29: CT Safety Factor | N29: n | O29: = | P29: 10
B30: Safety Factor among all connected devices Fs (min) | O30: = | P30: 20 | R30: ** | S30: Assumed
C32: Minimum Safety Factor among all connected devices | Q32: Fs(min) | R32: = | S32: 20 | V32: **
C34: Total connected burden on CT | I34: = | J34: Connected devices burden | P34: + | Q34: Lead Burden
I35: = | J35: =J23 -> 0.70675935
H37: Effective Safety Factor of CT, FS' | I37: = | J37: FS | K37: x ( ( | L37: PE | M37: + | N37: PN | O37: ) / ( | P37: PE | Q37: + | R37: PL | S37: )
I38: = | J38: =H13 -> 10 | K38: x ( ( | L38: =P22 -> 8 | M38: + | N38: =H14 -> 7.5 | O38: ) / ( | P38: =P22 -> 8 | Q38: + | R38: =J23 -> 0.70675935 | S38: )
I39: = | J39: =J38*((L38+N38)/(P38+R38)) -> 17.802261
A41: CT is considered to be properly sized if following conditions are satisfied…
B42: 1 | H42: Rated CT Burden | I42: > | J42: Total Connected Burden | S42: …cond.1
G43: =H14 -> 7.5 | I43: =IF(G43>J43,">","<") -> > | J43: =J35 -> 0.70675935 | S43: =IF(G43>J43,"Satisfied","Not satisfied") -> Satisfied
B45: 2 | H45: FS(min) of connected devices | I45: > | J45: Effective Safety Factor of CT, FS' | S45: …cond.2
G46: =P30 -> 20 | I46: =IF(G46>J46,">","<") -> > | J46: =J39 -> 17.802261 | S46: =IF(G46>J46,"Satisfied","Not satisfied") -> Satisfied
H47: Hence CT is: | J47: =IF(AND(I43=">",I46=">")=TRUE,"Suitable Dimensions","Not suitable") -> Suitable Dimensions
B50: =B7 -> T1 | D50: =D7 -> Core4 | H50: =H7 -> (Tariff Meter- Check) | S50: Connected devices: | T50: =T7 -> XC-RACK
B51: =B8 -> 0 | T51: =T8 -> GOSSEN
...

Sheet BAY2
E22: Transformer (BC2 - 11, 07,06)

Sheet HVC1 - REF650
A1: HITACHI | H1: =[3]Title!H1 -> CT / VT | O1: =Title!O1 -> Contract No. | R1: =Title!R1 -> N-19957.1-DF5W
H2: =[3]Title!H2 -> ADEQUACY CHECK | O2: =Title!O2 -> Date | R2: =Title!R2 -> 46106
H3: =Title!H3 -> LT14 - LEWIS 400/132kV SUBSTATION | O3: =Title!O3 -> Document No. | R3: =Title!R3 -> -
O4: =Title!O4 -> Revision No. | R4: =Title!R4 -> A
A5: =[3]Title!A5 -> Prep. By | C5: =[3]Title!C5 -> AK | D5: =[3]Title!D5 -> Checked By | G5: =[3]Title!G5 -> LN | H5: Transformer | O5: =Title!O5 -> Contractor | R5: =Title!R5 -> HITACHI
B7: T1 | D7: Core1 | S7: Connected devices: | T7: REF650
H9: Tap-1 | J9: Tap-2 | L9: Tap-3
B10: CT Ratio: | H10: 1250 | J10: - | L10: - | N10: / | O10: 1 | P10: A
B11: Class of Accuracy: | H11: PX-B
B12: CT Resistance: | G12: Rct< | H12: 5 | J12: W
B13: Knee Point Voltage: | G13: Vk> | H13: 750 | J13: V | W13: =G56 -> Suitably Dimentioned
B14: Magnetizing Current: | G14: I0< | H14: 60 | J14: mA at Vk
A16: Other Burdens on same CT core:
B18: Burden of | D18: =T7 -> REF650 | I18: = | J18: ='CT-VT Burdens'!Q48 -> 0.02 | L18: VA | N18: CT internal Burden
B19: Burden of | D19: =T8 -> 0 | I19: = | L19: VA
B20: Burden of | D20: =T9 -> 0 | I20: = | L20: VA | N20: PE | O20: = | P20: In | Q20: x | R20: In | S20: x | T20: Rct
B21: Total lead burden | I21: = | J21: ='CT-VT Burdens'!S39 -> 2.7035015 | L21: VA | O21: = | P21: =O10 -> 1 | Q21: x | R21: =O10 -> 1 | S21: x | T21: =H12 -> 5
B22: Total lead + other burden | H22: PL | I22: = | J22: =SUM(J18:J21) -> 2.7235015 | L22: VA | O22: = | P22: =P21*R21*T21 -> 5 | R22: VA
A24: The design values according to BS can be approximately transferred in to IEC60044 Standard using the following formula:
C27: Vk | D27: = | E27: ( ( | F27: PN | G27: + | H27: PE | I27: ) x | J27: n | K27: ) / ( | L27: In | M27: x | N27: 1.3 | O27: )
A28: Or
C29: PN | D29: = | E29: ( ( | F29: 1.3 | G29: x | H29: Vk | J29: x | K29: In | L29: ) / | M29: n | N29: ) - | O29: PE
C31: Max through fault current at close in fault | Q31: Itkmax | R31: = | S31: ='Parameters & Fault Cal. (4)'!Q10 *1000 -> 50000 | U31: A
C32: CT Primary Current, | Q32: Ipn | R32: = | S32: =H10 -> 1250 | U32: A
C33: Rated Knee Point Voltage, | Q33: Vk | R33: = | S33: =H13 -> 750 | U33: V
C34: Internal Burden, | Q34: PE | R34: = | S34: =P22 -> 5 | U34: VA
C35: Burden of CT Leads and burden of connected devices | Q35: PL | R35: = | S35: =J22 -> 2.7235015 | U35: VA
C36: Rated Secondary Current, | Q36: In | R36: = | S36: =O10 -> 1 | U36: A
C37: CT Accuracy Limiting Factor | Q37: n | R37: = | S37: 20
C38: Rated CT Burden | Q38: PN | R38: = | S38: =E42 -> 43.75
C40: PN | D40: = | E40: ( ( | F40: 1.3 | G40: x | H40: Vk | J40: x | K40: In | L40: ) / | M40: n | N40: ) - | O40: PE
D41: = | E41: ( ( | F41: 1.3 | G41: x | H41: =S33 -> 750 | J41: x | K41: =S36 -> 1 | L41: ) / | M41: =S37 -> 20 | N41: ) - | O41: =S34 -> 5
D42: = | E42: =((F41*H41)/(K41*M41))-O41 -> 43.75 | G42: VA
E46: Required Kssc' | F46: = | G46: Itkmax | I46: / | J46: Ipn
F47: = | G47: =S31 -> 50000 | I47: / | J47: =S32 -> 1250
F48: = | G48: =G47/J47 -> 40
E50: Available (effective) Kssc' | F50: = | G50: n | H50: x ( ( | I50: PE | J50: + | K50: PN | L50: ) / ( | M50: PE | N50: + | O50: PL | P50: )
F51: = | G51: =S37 -> 20 | H51: x ( ( | I51: =S34 -> 5 | J51: + | K51: =E42 -> 43.75 | L51: ) / ( | M51: =S34 -> 5 | N51: + | O51: =S35 -> 2.7235015 | P51: )
F52: = | G52: =G51*((I51+K51)/(M51+O51)) -> 126.23808
E54: Available Kssc' | F54: =IF(D55>G55,">","<") -> > | G54: Required Kssc'
...

Sheet MFAC+MVTP
A1: HITACHI | H1: =[4]Title!H1 -> CT / VT | O1: =[4]Title!O1 -> Contract No. | R1: =Title!R1 -> N-19957.1-DF5W
H2: =[4]Title!H2 -> ADEQUACY CHECK | O2: =[4]Title!O2 -> Date | R2: =Title!R2 -> 46106
H3: =Title!H3 -> LT14 - LEWIS 400/132kV SUBSTATION | O3: =[4]Title!O3 -> Document No. | R3: =Title!R3 -> -
O4: =[4]Title!O4 -> Revision No. | R4: =Title!R4 -> A
A5: =[4]Title!A5 -> Prep. By | C5: =[4]Title!C5 -> AP | D5: =[4]Title!D5 -> Checked By | G5: =[4]Title!G5 -> RB | H5: Transformer | O5: =[4]Title!O5 -> Contractor | R5: =Title!R5 -> HITACHI
B7: T1 | D7: Core2 | S7: Connected devices: | T7: MFAC
T8: MVTP
H9: Tap-1 | J9: Tap-2 | L9: Tap-3
B10: CT Ratio: | H10: 1250 | J10: - | L10: - | N10: / | O10: 1 | P10: A
B11: Class of Accuracy: | H11: PX-B
B12: CT Resistance: | G12: Rct< | H12: 5 | J12: W
B13: Knee Point Voltage: | G13: Vk> | H13: 750 | J13: V | W13: =#REF! -> #REF!
B14: Magnetizing Current: | G14: I0< | H14: 60 | J14: mA at Vk
A16: Other Burdens on same CT core:
B18: Burden of | D18: =T7 -> MFAC | I18: = | J18: ='CT-VT Burdens'!Q48 -> 0.02 | L18: VA
B19: Burden of | D19: =T8 -> MVTP | I19: = | J19: ='CT-VT Burdens'!Q48 -> 0.02 | L19: VA
B20: Burden of | D20: =T9 -> 0 | I20: = | L20: VA
B21: Total lead burden | I21: = | J21: ='CT-VT Burdens'!S22 -> 0.44875935 | L21: VA
B22: Total lead + other burden | H22: PL | I22: = | J22: =SUM(J18:J21) -> 0.48875935 | L22: VA
C24: Max primary through fault current for which stability is required | Q24: IF | R24: = | S24: ='Parameters & Fault Cal. (4)'!M70 -> 28681.091 | U24: A
C25: CT Primary Current | Q25: Ipn | R25: = | S25: =H10 -> 1250 | U25: A
C26: Max secondary fault current (same for all feeders) | Q26: Ifmax | R26: = | S26: =S24/S25*O10 -> 22.944873 | U26: A
C27: Resistance of each lead between the relay and CT | Q27: 2Rw | R27: = | S27: =J22/O10*O10 -> 0.48875935 | U27: W
C28: Max primary contribution from a feeder to an internal fault | Q28: IFmax int | R28: = | S28: =20*S25 -> 25000 | U28: A
C29: Max secondary contribution from a feeder to an internal fault | Q29: Ifmax int | R29: = | S29: =S28/S25 -> 20 | U29: A
A31: The CT requirement is as follows:
A33: Criteria I
B35: Vk | D35: >= | E35: 2 | F35: x | G35: IF | I35: x ( | J35: Rct | L35: + | M35: 2Rw | O35: )
D36: = | E36: 2 | F36: x | G36: =S26 -> 22.944873 | I36: x ( | J36: =H12 -> 5 | L36: + | M36: =S27 -> 0.48875935 | O36: )
D37: = | E37: =E36*G36*(J36+M36) -> 251.87777
A39: Adequacy Check
F42: Available Vk | G42: =IF(E43>H43, ">","<") -> > | H42: Required Vk
E43: =H13 -> 750 | G43: =G42 -> > | H43: =E37 -> 251.87777
F45: Hence CT is: | H45: =IF(G43=">","Suitably Dimentioned","Under Dimentioned") -> Suitably Dimentioned
A49: Summary of available CT parameters and its suitability
A50: CT / Core | D50: Ratio (A) | G50: CT Cable m/mm2 | I50: Class | K50: Rct @ 75OC (Ω) | M50: Rated Vk (V) | O50: Im @ Vk (mA) | Q50: Connected Devices | S50: CT Suitability
A51: =B7 -> T1 | B51: =D7 -> Core2 | D51: =H10 -> 1250 | F51: =O10 -> 1 | G51: ='CT-VT Burdens'!S19 -> 50 | H51: ='CT-VT Burdens'!S10 -> 6 | I51: =H11 -> PX-B | K51: =H12 -> 5 | M51: =H13 -> 750 | O51: =H14 -> 60 | Q51: =IF(T8="",T7,IF(T9="",T7&" "&T8,T7&" "&T8&" "&T9)) -> MFAC MVTP | S51: =H45 -> Suitably Dimentioned
D52: - | K52: - | M52: - | O52: - | S52: -
D53: - | K53: - | M53: - | O53: - | S53: -

Sheet BUP BCU(2)
A1: HITACHI | H1: =[3]Title!H1 -> CT / VT | O1: =Title!O1 -> Contract No. | R1: =Title!R1 -> N-19957.1-DF5W
H2: =[3]Title!H2 -> ADEQUACY CHECK | O2: =Title!O2 -> Date | R2: =Title!R2 -> 46106
H3: =Title!H3 -> LT14 - LEWIS 400/132kV SUBSTATION | O3: =Title!O3 -> Document No. | R3: =Title!R3 -> -
O4: =Title!O4 -> Revision No. | R4: =Title!R4 -> A
A5: =[3]Title!A5 -> Prep. By | C5: =[3]Title!C5 -> AK | D5: =[3]Title!D5 -> Checked By | G5: =[3]Title!G5 -> LN | H5: Transformer | O5: =Title!O5 -> Contractor | R5: =Title!R5 -> HITACHI
B7: T1 | D7: Core3 | S7: Connected devices: | T7: REF650
T8: REC670
H9: Tap-1 | J9: Tap-2 | L9: Tap-3 | T9: IDM+18
B10: CT Ratio: | H10: 1250 | J10: - | L10: - | N10: / | O10: 1 | P10: A | T10: P141
B11: Class of Accuracy: | H11: 5P20 | T11: PQ100
B12: CT Resistance: | G12: Rct< | H12: 5 | J12: W | T12: PM7500
B13: Knee Point Voltage: | G13: Vk> | J13: V | W13: =G60 -> Suitably Dimentioned
B14: Magnetizing Current: | G14: I0< | J14: mA at Vk
A16: Other Burdens on same CT core:
B18: Burden of | D18: =T7 -> REF650 | I18: = | J18: ='CT-VT Burdens'!Q48 -> 0.02 | L18: VA | N18: CT internal Burden
B19: Burden of | D19: =T8 -> REC670 | I19: = | J19: ='CT-VT Burdens'!Q48 -> 0.02 | L19: VA
B20: Burden of | D20: =T9 -> IDM+18 | I20: = | J20: ='CT-VT Burdens'!Q92 -> 0.058 | L20: VA | N20: PE | O20: = | P20: In | Q20: x | R20: In | S20: x | T20: Rct
B21: Burden of | D21: =T10 -> P141 | J21: ='CT-VT Burdens'!Q100 -> 0.04
B22: Burden of | D22: =T11 -> PQ100
B23: Total lead burden | I23: = | J23: ='CT-VT Burdens'!S22 -> 0.44875935 | L23: VA | O23: = | P23: =O10 -> 1 | Q23: x | R23: =O10 -> 1 | S23: x | T23: =H12 -> 5
B24: Total lead + other burden | H24: PL | I24: = | J24: =SUM(J18:J23) -> 0.58675935 | L24: VA | O24: = | P24: =P23*R23*T23 -> 5 | R24: VA
A26: The design values according to BS can be approximately transferred in to IEC60044 Standard using the following formula: | W26: The design values according to BS can be approximately transferred in to IEC60044 Standard using the following formula:
C29: Vk | D29: = | E29: ( ( | F29: PN | G29: + | H29: PE | I29: ) x | J29: n | K29: ) / ( | L29: In | M29: x | N29: 1.3 | O29: )
A30: Or
C31: PN | D31: = | E31: ( ( | F31: 1.3 | G31: x | H31: Vk | J31: x | K31: In | L31: ) / | M31: n | N31: ) - | O31: PE
C33: Max through fault current at close in fault | Q33: Itkmax | R33: = | S33: ='Parameters & Fault Cal. (4)'!Q32 -> 50000 | U33: A
C34: CT Primary Current, | Q34: Ipn | R34: = | S34: =H10 -> 1250 | U34: A
C35: Rated Knee Point Voltage, | Q35: Vk | R35: = | S35: =H13 -> 0 | U35: V
C36: Internal Burden, | Q36: PE | R36: = | S36: =P24 -> 5 | U36: VA
C37: Burden of CT Leads and burden of connected devices | Q37: PL | R37: = | S37: =J24 -> 0.58675935 | U37: VA
C38: Rated Secondary Current, | Q38: In | R38: = | S38: =O10 -> 1 | U38: A
C39: CT Accuracy Limiting Factor | Q39: n | R39: = | S39: 20
C40: Rated CT Burden | Q40: PN | R40: = | S40: 30
C44: PN | D44: = | E44: ( ( | F44: 1.3 | G44: x | H44: Vk | J44: x | K44: In | L44: ) / | M44: n | N44: ) - | O44: PE
D45: = | E45: ( ( | F45: 1.3 | G45: x | H45: =S35 -> 0 | J45: x | K45: =S38 -> 1 | L45: ) / | M45: =S39 -> 20 | N45: ) - | O45: =S36 -> 5
D46: = | E46: =((F45*H45)/(K45*M45))-O45 -> -5 | G46: VA
E50: Required Kssc' | F50: = | G50: Itkmax | I50: / | J50: Ipn
F51: = | G51: =S33 -> 50000 | I51: / | J51: =S34 -> 1250
F52: = | G52: =G51/J51 -> 40
E54: Available (effective) Kssc' | F54: = | G54: n | H54: x ( ( | I54: PE | J54: + | K54: PN | L54: ) / ( | M54: PE | N54: + | O54: PL | P54: )
...

Sheet BBP FU1 - REB500 (2)
A1: HITACHI | H1: =Title!H1 -> CT / VT | O1: =Title!O1 -> Contract No. | R1: =Title!R1 -> N-19957.1-DF5W
H2: =Title!H2 -> ADEQUACY CHECK | O2: =Title!O2 -> Date | R2: =Title!R2 -> 46106
H3: =Title!H3 -> LT14 - LEWIS 400/132kV SUBSTATION | O3: =Title!O3 -> Document No. | R3: =Title!R3 -> -
O4: =Title!O4 -> Revision No. | R4: =Title!R4 -> A
A5: =Title!A5 -> Prep. By | C5: =Title!C5 -> AP | D5: =Title!D5 -> Checked By | G5: =Title!G5 -> RB | H5: Transformer | O5: =Title!O5 -> Contractor | R5: =Title!R5 -> HITACHI
B7: T1 | D7: Core4 | S7: Connected devices: | T7: REB500
H9: Tap-1 | J9: Tap-2 | L9: Tap-3
B10: CT Ratio: | H10: 2500 | J10: - | L10: - | N10: / | O10: 1 | P10: A
B11: Class of Accuracy: | H11: PX-B
B12: CT Resistance: | G12: Rct< | H12: 5 | J12: W
B13: Knee Point Voltage: | G13: Vk> | H13: 750 | J13: V | W13: =#REF! -> #REF!
B14: Magnetizing Current: | G14: I0< | H14: 60 | J14: mA at Vk
A16: Other Burdens on same CT core:
B18: Burden of | D18: =T7 -> REB500 | I18: = | J18: ='CT-VT Burdens'!Q49 -> 0.01 | L18: VA | N18: CT internal Burden
B19: Burden of | D19: =T8 -> 0 | I19: = | L19: VA | N19: PE | O19: = | P19: In | Q19: x | R19: In | S19: x | T19: Rct
B20: Burden of | D20: =T9 -> 0 | I20: = | L20: VA | O20: = | P20: =O10 -> 1 | Q20: x | R20: =O10 -> 1 | S20: x | T20: =H12 -> 5
B21: Total lead burden | I21: = | J21: ='CT-VT Burdens'!S22 -> 0.44875935 | L21: VA | O21: = | P21: =P20*R20*T20 -> 5 | R21: VA
B22: Total lead + other burden | H22: PL | I22: = | J22: =SUM(J18:J21) -> 0.45875935 | L22: VA
B24: CT-Requirements for BB Protection
C25: Maximum Primary Fault Current | Q25: Isc | R25: = | S25: ='Parameters & Fault Cal. (4)'!Q10 *1000 -> 50000 | U25: A
C26: CT Primary Current, | Q26: Ipn | R26: = | S26: =H10 -> 2500 | U26: A
C27: Rated Voltage | Q27: UN2 | R27: = | S27: 400 | U27: kV
C28: Rated Knee Point Voltage, | Q28: Vk | R28: = | S28: =H13 -> 750 | U28: V
C29: Internal Resistance CT | Q29: Rct | R29: = | S29: =P21 -> 5 | U29: VA
C30: Conn. Lead + Relay Burden | Q30: RL | R30: = | S30: =J22 -> 0.45875935 | U30: VA
C31: Rated Secondary Current, | Q31: Isc | R31: = | S31: =O10 -> 1 | U31: A
C32: Nominal Frequency of the network | Q32: fn | R32: = | S32: 50
C34: Required OC factor condition. 1:
D35: At Max. Through fault current CT’s shall not saturate for currents below 5 times rated current.
I36: n' | J36: = | K36: Isc
K37: 5 * Ipn
C38: Required OC factor Condition 2:
D39: n2' >= 10 for TN <=120 msec
D40: n2' >= 20 for 120ms <= TN <=300 ms
B41: Where, | D41: n' = Required OC factor
D42: Isc = max. bus fault current
D43: Ipn = Rated primary current (A)
AB45: ** | AC45: Rated Bus fault current
B48: Required OC factor condition 1:
C50: n'(1) | D50: = | E50: =S25 -> 50000
...

Sheet BBP 743(2)
A1: HITACHI | H1: =[4]Title!H1 -> CT / VT | O1: =[4]Title!O1 -> Contract No. | R1: =Title!R1 -> N-19957.1-DF5W
H2: =[4]Title!H2 -> ADEQUACY CHECK | O2: =[4]Title!O2 -> Date | R2: =Title!R2 -> 46106
H3: =Title!H3 -> LT14 - LEWIS 400/132kV SUBSTATION | O3: =[4]Title!O3 -> Document No. | R3: =Title!R3 -> -
O4: =[4]Title!O4 -> Revision No. | R4: =Title!R4 -> A
A5: =[4]Title!A5 -> Prep. By | C5: =[4]Title!C5 -> AP | D5: =[4]Title!D5 -> Checked By | G5: =[4]Title!G5 -> RB | H5: Transformer | O5: =[4]Title!O5 -> Contractor | R5: =Title!R5 -> HITACHI
B7: T1 | D7: Core5 | S7: Connected devices: | T7: P743
H9: Tap-1 | J9: Tap-2 | L9: Tap-3
B10: CT Ratio: | H10: 2500 | J10: - | L10: - | N10: / | O10: 1 | P10: A
B11: Class of Accuracy: | H11: PX-B
