Workbook
Name ____________DAD11: #REF!
Name __________DAD11: #REF!
Name _________DAD11: #REF!
Name _________DAD11: #REF!
Name _________DAD11: #REF!
Name _________DAD11: #REF!
Name _________DAD11: #REF!
Name _________DAD11: #REF!
Name _________DAD11: #REF!
Name _________DAD11: #REF!
Name _________DAD11: #REF!
Name _________DAD11: #REF!
Name _________DAD11: #REF!
Name _________DAD11: #REF!
Name _________DAD11: #REF!
Name _________DAD11: #REF!
Name ________DAD11: #REF!
Name _______DAD11: #REF!
Name ______DAD11: #REF!
Name _____DAD11: #REF!
Name ____DAD11: #REF!
Name ___DAD11: #REF!
Name ___DAD11: #REF!
Name ___DAD11: #REF!
Name ___DAD11: #REF!
Name ___DAD11: #REF!
Name __DAD11: #REF!
Name _DAD11: #REF!
Name a: #REF!
Name a: #REF!
Name a: #REF!
Name a: #REF!
Name a: #REF!
Name a: #REF!
Name a: #REF!
Name a: #REF!
Name a: #REF!
Name a: #REF!
Name a: #REF!
Name a: #REF!
Name a: #REF!
Name a: #REF!
Name a: #REF!
Name a: #REF!
Name a: #REF!
Name a: #REF!
Name a: #REF!
Name a: #REF!
Name a: #REF!
Name AA: #REF!
Name AA: #REF!
Name AA: #REF!
Name AA: #REF!
Name AA: #REF!
Name AA: #REF!
Name AA: #REF!
Name AA: #REF!
Name AA: #REF!
Name AA: #REF!
Name AA: #REF!

Sheet Title
A1: HITACHI | H1: CT / VT | O1: Contract No. | R1: N-19957.2-DF4W
H2: ADEQUACY CHECK | O2: Date | R2: 46134
H3: 132/33kV SUBSTATION DF4W AT AL DHAFRA AREA | O3: Document No. | R3: -
O4: Revision No. | R4: A
A5: Prep. By | C5: AP | D5: Checked By | G5: RB | H5: Title Sheet | O5: Contractor | R5: HITACHI
E17: =H3 -> 132/33kV SUBSTATION DF4W AT AL DHAFRA AREA
E20: CT/VT ADEQUACY CHECK
L22: CT & VT CALCULATIONS
M34: Hitachi
M35: Substation Automation Systems
M37: Date: | P37: =R2 -> 46134
M38: Prepared by: | P38: Arulprakasam K
M39: Checked by: | P39: Ramesh Babu
M40: Approved by: | P40: Rudresh N

Sheet INDEX
A1: =Title!A1 -> HITACHI | H1: =Title!H1 -> CT / VT | O1: =Title!O1 -> Contract No. | R1: =Title!R1 -> N-19957.2-DF4W
H2: =Title!H2 -> ADEQUACY CHECK | O2: =Title!O2 -> Date | R2: =Title!R2 -> 46134
H3: =Title!H3 -> 132/33kV SUBSTATION DF4W AT AL DHAFRA AREA | O3: =Title!O3 -> Document No. | R3: =Title!R3 -> -
O4: =Title!O4 -> Revision No. | R4: =Title!R4 -> A
A5: =Title!A5 -> Prep. By | C5: =Title!C5 -> AP | D5: =Title!D5 -> Checked By | G5: =Title!G5 -> RB | H5: Index | O5: =Title!O5 -> Contractor | R5: =Title!R5 -> HITACHI
C8: INDEX
R10: Pg:No
C11: 1 | D11: NOTES | N11: Page 4 of 25 | R11: 3
C12: 2 | D12: SUMMARY SHEET | N12: Page 5 of 25 | R12: 4 | Y12: CT / VT Data Summary
C13: 3 | D13: CT/VT BURDEN DETAILS | Q13: - | R13: 11
C14: 4 | D14: CT ADEQUACY CHECK | R14: 14
C15: 5 | D15: PARAMETERS AND FAULT CALCULATIONS | Q15: - | R15: 15 | Y15: Parameters & Fault Calculations
C16: 6 | D16: 132KV CABLE FEEDERS | R16: 19
C17: 7 | D17: 132kV_100MVA TR. FEEDERS | R17: 47
D18: 132kV_100MVA TR. FEEDERS
C19: 8 | D19: 132kV_CAPACITOR BANK
C20: 9 | D20: 132kV BUS COUPLER | R20: 118
C21: 10 | D21: 132kV BUS SECTION | R21: 127
C22: 11 | D22: VT ADEQUACY CHECK | R22: 136
C23: 12 | D23: 132KV CABLE FEEDER VT | R23: 137
C24: 13 | D24: 132kV BUS VT
AD31: Supporting Documents
C32: ANNEXURE-A | G32: Over All SLD | R32: 141 | AD32: Annexure- A | AG32: Relays Burden
C33: ANNEXURE-B | G33: Input requirements list | R33: 144 | AD33: Annexure- B | AG33: CT requirements of RET670
C34: ANNEXURE-C | G34: CT requirements of RED670 | R34: 150 | AD34: Annexure- C | AG34: CT requirements of RET615
C35: ANNEXURE-D | G35: CT requirements of REF615 | R35: 160 | AD35: Annexure- D | AG35: CT requirements of REF615
C36: ANNEXURE-E | G36: CT requirements of REC670 | R36: 170 | AD36: Annexure- E | AG36: ESI Standard 48-3
C37: ANNEXURE-F | G37: CT requirements of REB500 | R37: 174
C38: ANNEXURE-G | G38: CT requirements of P545 | R38: 127 | AD38: Annexure- E | AG38: ESI Standard 48-3
C39: ANNEXURE-H | G39: CT requirements of 7SL86 | R39: 249 | AD39: Annexure- F | AG39: 220kV SS-516 SLD
C40: ANNEXURE-I | G40: CT requirements of SEL487E | R40: 255
C41: ANNEXURE-H | G41: CT requirements of IDM+X | R41: 137
C42: ANNEXURE-G | G42: CT requirements of RET670 | R42: 178
C43: ANNEXURE-H | G43: CT requirements of 7SL86 | R43: 188
C44: ANNEXURE-I | G44: CT requirements of 7UT85 | R44: 200
C45: ANNEXURE-J | G45: CT requirements of 6MD85 | R45: 217
C46: ANNEXURE-K | G46: CT requirements of CP-L96A | R46: 221

Sheet Notes Or Assumptions
A1: HITACHI | H1: =Title!H1 -> CT / VT | O1: =Title!O1 -> Contract No. | R1: =Title!R1 -> N-19957.2-DF4W
H2: =Title!H2 -> ADEQUACY CHECK | O2: =Title!O2 -> Date | R2: =Title!R2 -> 46134
H3: =Title!H3 -> 132/33kV SUBSTATION DF4W AT AL DHAFRA AREA | O3: =Title!O3 -> Document No. | R3: =Title!R3 -> -
O4: =Title!O4 -> Revision No. | R4: =Title!R4 -> A
A5: =Title!A5 -> Prep. By | C5: =Title!C5 -> AP | D5: =Title!D5 -> Checked By | G5: =Title!G5 -> RB | H5: Notes | O5: =Title!O5 -> Contractor | R5: =Title!R5 -> HITACHI
C8: Notes
B10: 1 | C10: The maximum CT lead length from the SWGR CT secondary terminal to relay terminals are considered as 160m
B12: 2 | C12: Size of the CT lead considered as 6 Sq. mm for calculation | Z12: 165m Lead Resistance of the current loop from the 33kV Incomer SWGR to 220kV Transformer Protection Panel.
B13: 3 | C13: The maximum VT lead length from the VT secondary terminal to relay terminals are considered as 160m
B14: 4 | C14: Size of the VT lead considered as 2.5 Sq. mm for calculation
B15: 5 | C15: Bus fault level is considered as 50 kA/3s for 132kV
B16: 6 | C16: X/R ratio is considered as 15 for 132kV system.
G54: Notes
G55: 1. CT Adequacy Check calculation of Remote End Cable Feeders are part of different submission
G56: 2. The CT sizing calculation is done for two type of relays RED670 and 7SD522 for cable feeders
G57: 3. Class X type CTs are proposed against that of Class TPS type CTs as per SOW
H63: Note:
G64: 1 | H64: This Calculation is Applicable for all the three S/S
G65: 2
H66: MV Max. Bus fault level/Switchgear Rating is assumed as 31.5kA as per Specification S-AAA-GEN-SFL (REV.0-2011) clause 3
H67: MV X/R Ratio is assumed as 15
H68: LV Max. Bus fault level/Switchgear Rating is assumed as 25kA as per Specification S-AAA-GEN-SFL (REV.0-2011) clause 3
H69: LV X/R Ratio is assumed as 15
H70: Power Cable Type is assumed as CU XLPE type .
H71: Positive Sequence Resistance, Positive Sequence Reactance , Zero Sequence Resistance and Zero Sequence Reactance of the power cable are assumed
H72: Route Length of the power cable is assumed as 5km
H73: Minimum 33kV Busbar Fault Current is Assumed as 20kA
H74: 33/11kV Transformer Impedance is Assumed to be 12%

Sheet CT-VT Data landscape
A1: HITACHI | H1: =Title!H1&" "&Title!H2 -> CT / VT ADEQUACY CHECK | T1: =Title!O1 -> Contract No. | W1: =Title!R1 -> N-19957.2-DF4W
T2: =Title!O2 -> Date | W2: =Title!R2 -> 46134
H3: =Title!H3 -> 132/33kV SUBSTATION DF4W AT AL DHAFRA AREA | T3: =Title!O3 -> Document No. | W3: =Title!R3 -> -
T4: =Title!O4 -> Revision No. | W4: =Title!R4 -> A
A5: =Title!A5 -> Prep. By | C5: =Title!C5 -> AP | D5: =Title!D5 -> Checked By | G5: =Title!G5 -> RB | H5: Summary Sheet | T5: =Title!O5 -> Contractor | W5: =Title!R5 -> HITACHI
H7: CT parameters (Summary)
A8: 220/132kV Over All Transformer Differential (320MVA) Q08, Q13
A9: (Transformer Differential - 132kV side CT)
A10: CT / Core | D10: Ratio (A) | G10: CT Cable m/mm2 | I10: Class | K10: Rct @ 75OC (Ω) | M10: Rated Vk (V) | O10: Im @ Vk (mA) | Q10: Connected Devices | S10: CT Suitability | W10: Required Vk (V)
A11: ='[2]RET670_650-PX (LV)'!A398 -> BC1 | B11: ='[2]RET670_650-PX (LV)'!B398 -> Core1 | D11: ='[2]RET670_650-PX (LV)'!D398 -> 1500 | F11: ='[2]RET670_650-PX (LV)'!F398 -> 1 | G11: ='[2]RET670_650-PX (LV)'!G398 -> 50 | H11: ='[2]RET670_650-PX (LV)'!H398 -> 2.5 | I11: ='[2]RET670_650-PX (LV)'!I398 -> PX | K11: ='[2]RET670_650-PX (LV)'!K398 -> 3 | M11: ='[2]RET670_650-PX (LV)'!M398 -> 1500 | O11: ='[2]RET670_650-PX (LV)'!O398 -> 37.76 | Q11: ='[2]RET670_650-PX (LV)'!Q398 -> RET670 | S11: ='[2]RET670_650-PX (LV)'!S398 -> Suitably Dimensioned | W11: ='[2]RET670_650-PX (LV)'!H100 -> 94.143205
D12: ='[2]RET670_650-PX (LV)'!D399 -> - | K12: ='[2]RET670_650-PX (LV)'!K399 -> - | M12: ='[2]RET670_650-PX (LV)'!M399 -> - | O12: ='[2]RET670_650-PX (LV)'!O399 -> - | S12: - | W12: -
D13: ='[2]RET670_650-PX (LV)'!D400 -> - | K13: ='[2]RET670_650-PX (LV)'!K400 -> - | M13: ='[2]RET670_650-PX (LV)'!M400 -> - | O13: ='[2]RET670_650-PX (LV)'!O400 -> - | S13: ='[2]RET670_650-PX (LV)'!S400 -> - | W13: -
A14: (Transformer Differential - 220kV side CT)
A15: CT / Core | D15: Ratio (A) | G15: CT Cable m/mm2 | I15: Class | K15: Rct @ 75OC (Ω) | M15: Rated Vk (V) | O15: Im @ Vk (mA) | Q15: Connected Devices | S15: CT Suitability | W15: Required Vk (V)
A16: ='[2]RET670_650-PX (HV-T12) '!A398 -> T12 | B16: ='[2]RET670_650-PX (HV-T12) '!B398 -> Core1 | D16: ='[2]RET670_650-PX (HV-T12) '!D398 -> 1200 | F16: ='[2]RET670_650-PX (HV-T12) '!F398 -> 1 | G16: ='[2]RET670_650-PX (HV-T12) '!G398 -> 50 | H16: ='[2]RET670_650-PX (HV-T12) '!H398 -> 2.5 | I16: ='[2]RET670_650-PX (HV-T12) '!I398 -> PX | K16: ='[2]RET670_650-PX (HV-T12) '!K398 -> 5 | M16: ='[2]RET670_650-PX (HV-T12) '!M398 -> 1000 | O16: ='[2]RET670_650-PX (HV-T12) '!O398 -> 30 | Q16: ='[2]RET670_650-PX (HV-T12) '!Q398 -> RET670 | S16: ='[2]RET670_650-PX (HV-T12) '!S398 -> Suitably Dimensioned | W16: ='[2]RET670_650-PX (HV-T12) '!H100 -> 177.39685
D17: ='[2]RET670_650-PX (HV-T12) '!D399 -> - | K17: ='[2]RET670_650-PX (HV-T12) '!K399 -> - | M17: ='[2]RET670_650-PX (HV-T12) '!M399 -> - | O17: ='[2]RET670_650-PX (HV-T12) '!O399 -> - | S17: ='[2]RET670_650-PX (HV-T12) '!S399 -> - | W17: -
D18: ='[2]RET670_650-PX (HV-T12) '!D400 -> - | K18: ='[2]RET670_650-PX (HV-T12) '!K400 -> - | M18: ='[2]RET670_650-PX (HV-T12) '!M400 -> - | O18: ='[2]RET670_650-PX (HV-T12) '!O400 -> - | S18: ='[2]RET670_650-PX (HV-T12) '!S400 -> - | W18: -
A19: (OCEF Protection)
A20: CT / Core | D20: Ratio (A) | G20: CT Cable m/mm2 | I20: Class | K20: Rct @ 75OC (Ω) | M20: Rated Vk (V) | O20: Im @ Vk (mA) | Q20: Connected Devices | S20: CT Suitability | W20: Required Vk (V)
A21: ='[2]REF615 OC-5P (5)'!A141 -> BC1 | B21: ='[2]REF615 OC-5P (5)'!B141 -> Core3 | D21: ='[2]REF615 OC-5P (5)'!D141 -> 1500 | F21: ='[2]REF615 OC-5P (5)'!F141 -> 1 | G21: ='[2]REF615 OC-5P (5)'!G141 -> 50 | H21: ='[2]REF615 OC-5P (5)'!H141 -> 2.5 | I21: ='[2]REF615 OC-5P (5)'!I141 -> 5P | K21: ='[2]REF615 OC-5P (5)'!K141 -> 4 | M21: ='[2]REF615 OC-5P (5)'!M141 -> 30 | O21: ='[2]REF615 OC-5P (5)'!O141 -> - | Q21: ='[2]REF615 OC-5P (5)'!Q141 -> REF615+REF615 | S21: ='[2]REF615 OC-5P (5)'!S141 -> Suitably Dimensioned | W21: ='[2]REF615 OC-5P (5)'!G40 -> 26.666667
D22: ='[2]REF615 OC-5P (5)'!D142 -> - | K22: ='[2]REF615 OC-5P (5)'!K142 -> - | M22: ='[2]REF615 OC-5P (5)'!M142 -> - | O22: ='[2]REF615 OC-5P (5)'!O142 -> - | S22: ='[2]REF615 OC-5P (5)'!S142 -> - | W22: -
D23: ='[2]REF615 OC-5P (5)'!D143 -> - | K23: ='[2]REF615 OC-5P (5)'!K143 -> - | M23: ='[2]REF615 OC-5P (5)'!M143 -> - | O23: ='[2]REF615 OC-5P (5)'!O143 -> - | S23: ='[2]REF615 OC-5P (5)'!S143 -> - | W23: -
A24: (Low Imp. Busbar - 132kV side CT)
A25: CT / Core | D25: Ratio (A) | G25: CT Cable m/mm2 | I25: Class | K25: Rct @ 75OC (Ω) | M25: Rated Vk (V) | O25: Im @ Vk (mA) | Q25: Connected Devices | S25: CT Suitability | W25: Required Vk (V)
A26: ='[2]REB500-PX (5)'!A260 -> BC1 | B26: ='[2]REB500-PX (5)'!B260 -> Core5 | D26: ='[2]REB500-PX (5)'!D260 -> 3150 | F26: ='[2]REB500-PX (5)'!F260 -> 1 | G26: ='[2]REB500-PX (5)'!G260 -> 100 | H26: ='[2]REB500-PX (5)'!H260 -> 4 | I26: ='[2]REB500-PX (5)'!I260 -> PX | K26: ='[2]REB500-PX (5)'!K260 -> 10 | M26: ='[2]REB500-PX (5)'!M260 -> 3150 | O26: ='[2]REB500-PX (5)'!O260 -> 210.8 | Q26: ='[2]REB500-PX (5)'!Q260 -> REB500 | S26: ='[2]REB500-PX (5)'!S260 -> Suitably Dimensioned | W26: ='[2]REB500-PX (5)'!G148 -> 10
D27: ='[2]REB500-PX (5)'!D261 -> 1500 | K27: ='[2]REB500-PX (5)'!K261 -> 5 | M27: ='[2]REB500-PX (5)'!M261 -> 1000 | O27: ='[2]REB500-PX (5)'!O261 -> 147.73 | S27: ='[2]REB500-PX (5)'!S261 -> Suitably Dimensioned | W27: -
D28: ='[2]REB500-PX (5)'!D262 -> - | K28: ='[2]REB500-PX (5)'!K262 -> - | M28: ='[2]REB500-PX (5)'!M262 -> - | O28: ='[2]REB500-PX (5)'!O262 -> - | S28: ='[2]REB500-PX (5)'!S262 -> - | W28: -
A33: (Hi Imp. REF - 132kV Side CT)
A34: CT / Core | D34: Ratio (A) | G34: CT Cable m/mm2 | I34: Class | K34: Rct @ 75OC (Ω) | M34: Rated Vk (V) | O34: Im @ Vk (mA) | Q34: Connected Devices | S34: CT Suitability | W34: Required Vk (V)
A35: ='[2]RET615_Trafo LV REF (High)'!A91 -> BC1 | B35: ='[2]RET615_Trafo LV REF (High)'!B91 -> Core2 | D35: ='[2]RET615_Trafo LV REF (High)'!D91 -> 1500 | F35: ='[2]RET615_Trafo LV REF (High)'!F91 -> 1 | G35: ='[2]RET615_Trafo LV REF (High)'!G91 -> 50 | H35: ='[2]RET615_Trafo LV REF (High)'!H91 -> 2.5 | I35: ='[2]RET615_Trafo LV REF (High)'!I91 -> PX | K35: ='[2]RET615_Trafo LV REF (High)'!K91 -> 3 | M35: ='[2]RET615_Trafo LV REF (High)'!M91 -> 1500 | O35: ='[2]RET615_Trafo LV REF (High)'!O91 -> 74.39 | Q35: ='[2]RET615_Trafo LV REF (High)'!Q91 -> RET615 | S35: ='[2]RET615_Trafo LV REF (High)'!S91 -> Suitably Dimensioned | W35: ='[2]RET615_Trafo LV REF (High)'!G78 -> 308.19171
D36: ='[2]RET615_Trafo LV REF (High)'!D92 -> - | K36: ='[2]RET615_Trafo LV REF (High)'!K92 -> - | M36: ='[2]RET615_Trafo LV REF (High)'!M92 -> - | O36: ='[2]RET615_Trafo LV REF (High)'!O92 -> - | S36: ='[2]RET615_Trafo LV REF (High)'!S92 -> -
D37: ='[2]RET615_Trafo LV REF (High)'!D93 -> - | K37: ='[2]RET615_Trafo LV REF (High)'!K93 -> - | M37: ='[2]RET615_Trafo LV REF (High)'!M93 -> - | O37: ='[2]RET615_Trafo LV REF (High)'!O93 -> - | S37: ='[2]RET615_Trafo LV REF (High)'!S93 -> -
A38: ='[2]RET615_Trafo LV REF (High)'!A94 -> T2N | B38: ='[2]RET615_Trafo LV REF (High)'!B94 -> Core1 | D38: ='[2]RET615_Trafo LV REF (High)'!D94 -> 1500 | F38: ='[2]RET615_Trafo LV REF (High)'!F94 -> 1 | G38: ='[2]RET615_Trafo LV REF (High)'!G94 -> 50 | H38: ='[2]RET615_Trafo LV REF (High)'!H94 -> 2.5 | I38: ='[2]RET615_Trafo LV REF (High)'!I94 -> PX | K38: ='[2]RET615_Trafo LV REF (High)'!K94 -> 10 | M38: ='[2]RET615_Trafo LV REF (High)'!M94 -> 1500 | O38: ='[2]RET615_Trafo LV REF (High)'!O94 -> 100 | Q38: ='[2]RET615_Trafo LV REF (High)'!Q94 -> RET615 | S38: ='[2]RET615_Trafo LV REF (High)'!S94 -> Suitably Dimensioned | W38: ='[2]RET615_Trafo LV REF (High)'!G78 -> 308.19171
D39: ='[2]RET615_Trafo LV REF (High)'!D95 -> - | K39: ='[2]RET615_Trafo LV REF (High)'!K95 -> - | M39: ='[2]RET615_Trafo LV REF (High)'!M95 -> - | O39: ='[2]RET615_Trafo LV REF (High)'!O95 -> - | S39: ='[2]RET615_Trafo LV REF (High)'!S95 -> -
D40: ='[2]RET615_Trafo LV REF (High)'!D96 -> - | K40: ='[2]RET615_Trafo LV REF (High)'!K96 -> - | M40: ='[2]RET615_Trafo LV REF (High)'!M96 -> - | O40: ='[2]RET615_Trafo LV REF (High)'!O96 -> - | S40: ='[2]RET615_Trafo LV REF (High)'!S96 -> -
A41: ='[2]RET615_Trafo LV REF (High)'!A97 -> 0 | B41: ='[2]RET615_Trafo LV REF (High)'!B97 -> 0 | D41: ='[2]RET615_Trafo LV REF (High)'!D97 -> 1500 | F41: ='[2]RET615_Trafo LV REF (High)'!F97 -> 1 | G41: ='[2]RET615_Trafo LV REF (High)'!G97 -> 50 | H41: ='[2]RET615_Trafo LV REF (High)'!H97 -> 2.5 | I41: ='[2]RET615_Trafo LV REF (High)'!I97 -> PX | K41: ='[2]RET615_Trafo LV REF (High)'!K97 -> 3 | M41: ='[2]RET615_Trafo LV REF (High)'!M97 -> 1500 | O41: ='[2]RET615_Trafo LV REF (High)'!O97 -> 74.39 | Q41: ='[2]RET615_Trafo LV REF (High)'!Q97 -> RET615 | S41: ='[2]RET615_Trafo LV REF (High)'!S97 -> Suitably Dimensioned | W41: ='[2]RET615_Trafo LV REF (High)'!G78 -> 308.19171
D42: ='[2]RET615_Trafo LV REF (High)'!D98 -> - | K42: ='[2]RET615_Trafo LV REF (High)'!K98 -> - | M42: ='[2]RET615_Trafo LV REF (High)'!M98 -> - | O42: ='[2]RET615_Trafo LV REF (High)'!O98 -> - | S42: ='[2]RET615_Trafo LV REF (High)'!S98 -> -
D43: ='[2]RET615_Trafo LV REF (High)'!D99 -> - | K43: ='[2]RET615_Trafo LV REF (High)'!K99 -> - | M43: ='[2]RET615_Trafo LV REF (High)'!M99 -> - | O43: ='[2]RET615_Trafo LV REF (High)'!O99 -> - | S43: ='[2]RET615_Trafo LV REF (High)'!S99 -> -
A44: (BCU)
A45: CT / Core | D45: Ratio (A) | G45: CT Cable m/mm2 | I45: Class | K45: Rct @ 75OC (Ω) | M45: Rated Burden (VA) | Q45: Connected Devices | S45: CT Suitability
...

Sheet CT-VT Burdens
A1: HITACHI | H1: =Title!H1 -> CT / VT | O1: =Title!O1 -> Contract No. | R1: =Title!R1 -> N-19957.2-DF4W
H2: =Title!H2 -> ADEQUACY CHECK | O2: =Title!O2 -> Date | R2: =Title!R2 -> 46134
H3: =Title!H3 -> 132/33kV SUBSTATION DF4W AT AL DHAFRA AREA | O3: =Title!O3 -> Document No. | R3: =Title!R3 -> -
O4: =Title!O4 -> Revision No. | R4: =Title!R4 -> A
A5: =Title!A5 -> Prep. By | C5: =Title!C5 -> AP | D5: =Title!D5 -> Checked By | G5: =Title!G5 -> RB | H5: CT / VT Burdens | O5: =Title!O5 -> Contractor | R5: =Title!R5 -> HITACHI
B8: For CT Wiring
B9: Burden of the connecting leads :
C10: Conductor cross section in mm2 | Q10: A | R10: = | S10: 6 | U10: mm2 | V10: **
C11: Resistance in W/km at 200 C | Q11: R20 | R11: = | S11: 3.69 | U11: Ω/km | X11: 7.41
C12: Specific resistance at 200 C | I12: (copper wires) | Q12: a | R12: = | S12: 0.00393 | U12: K-1
B14: Resistance in Ω/km at t0 C = | H14: R20 [ 1 + a ( t - 200 C ) ]
C15: Resistance in ohms/km at 750 C = | R15: = | S15: =S11*(1+S12*(75-20)) -> 4.4875935 | U15: Ω/km | X15: =S11*(1+S12*(75-20)) -> 4.4875935 | Z15: 5.61
C16: Resistance in ohms/m at 750 C = | Q16: R | R16: = | S16: =S15/1000 -> 0.0044875935 | U16: Ω/m
C17: Secondary current of CT | Q17: Is | R17: = | S17: 1 | U17: A
C18: Relay Rated current | Q18: Ir | R18: = | S18: 1 | U18: A
C21: Conductor length in meters ( CT to relay ) | Q21: l | R21: = | S21: 120 | U21: m | V21: **
C22: Lead Resistance from the CT to Relay | Q22: RL =R x l | R22: = | S22: =S16*S21 -> 0.53851122 | U22: Ω
C23: Lead Resistance of the current loop from the CT to Relay | Q23: 2RL = 2 x R x l | R23: = | S23: =2*S16*S21 -> 1.0770224 | U23: Ω | X23: =2*S16*S21 -> 1.0770224 | Z23: =2*S16*S21 -> 1.0770224
C24: VA consumption of the connecting leads | Q24: Pl = Is2 x Rl | R24: = | S24: =S17*S17*S23 -> 1.0770224 | U24: VA | X24: =S17*S17*S23 -> 1.0770224
C26: For 132kV_100MVA TR. FEEDERS
C27: Conductor length in meters ( CT to relay ) | Q27: l | R27: = | S27: 130 | U27: m | V27: **
C28: Lead Resistance from the CT to Relay | Q28: RL =R x l | R28: = | S28: =S16*S27 -> 0.58338716 | U28: Ω
C29: Lead Resistance of the current loop from the CT to Relay | Q29: 2RL = 2 x R x l | R29: = | S29: =2*S28 -> 1.1667743 | U29: Ω
C30: VA consumption of the connecting leads | Q30: Pl = Is2 x Rl | R30: = | S30: =S17*S17*S29 -> 1.1667743 | U30: VA
C32: For 132kV_IBT INCOMER FEEDERS
C33: Conductor length in meters ( CT to relay ) | Q33: l | R33: = | S33: 140 | U33: m | V33: **
C34: Lead Resistance from the CT to Relay | Q34: RL =R x l | R34: = | S34: =S16*S33 -> 0.62826309 | U34: Ω
C35: Lead Resistance of the current loop from the CT to Relay | Q35: 2RL = 2 x R x l | R35: = | S35: =2*S34 -> 1.2565262 | U35: Ω
C36: VA consumption of the connecting leads | Q36: Pl = Is2 x Rl | R36: = | S36: =S17*S17*S35 -> 1.2565262 | U36: VA
C38: For 132kV BUS SECTION
C39: Conductor length in meters ( CT to relay ) | Q39: l | R39: = | S39: 160 | U39: m | V39: **
C40: Lead Resistance from the CT to Relay | Q40: RL =R x l | R40: = | S40: =S16*S39 -> 0.71801496 | U40: Ω
C41: Lead Resistance of the current loop from the CT to Relay | Q41: 2RL = 2 x R x l | R41: = | S41: =2*S40 -> 1.4360299 | U41: Ω
C42: VA consumption of the connecting leads | Q42: Pl = Is2 x Rl | R42: = | S42: =S17*S17*S41 -> 1.4360299 | U42: VA
C43: 165m Lead Resistance of the current loop from the 33kV Incomer SWGR to 220kV Transformer Protection Panel. | S43: =S16*165 -> 0.74045293 | U43: VA
C48: For 132kV BUS COUPLER
C49: Conductor length in meters ( CT to relay ) | Q49: l | R49: = | S49: 140 | U49: m | V49: **
C50: Lead Resistance from the CT to Relay | Q50: RL =R x l | R50: = | S50: =S16*S49 -> 0.62826309 | U50: Ω
C51: Lead Resistance of the current loop from the CT to Relay | Q51: 2RL = 2 x R x l | R51: = | S51: =2*S50 -> 1.2565262 | U51: Ω
C52: VA consumption of the connecting leads | Q52: Pl = Is2 x Rl | R52: = | S52: =S17*S17*S51 -> 1.2565262 | U52: VA
...

Sheet CT ADEQUACY
E22: CT ADEQUACY CHECK

Sheet Parameters & Fault Cal. (4)
A1: HITACHI | H1: =Title!H1 -> CT / VT | O1: =Title!O1 -> Contract No. | R1: =Title!R1 -> N-19957.2-DF4W
H2: =Title!H2 -> ADEQUACY CHECK | O2: =Title!O2 -> Date | R2: =Title!R2 -> 46134
H3: =Title!H3 -> 132/33kV SUBSTATION DF4W AT AL DHAFRA AREA | O3: =Title!O3 -> Document No. | R3: =Title!R3 -> -
O4: =Title!O4 -> Revision No. | R4: =Title!R4 -> A
A5: =Title!A5 -> Prep. By | C5: =Title!C5 -> AP | D5: =Title!D5 -> Checked By | G5: =Title!G5 -> RB | H5: Parameters & Fault Calculations for 132kV FEEDERS | O5: =Title!O5 -> Contractor | R5: =Title!R5 -> HITACHI
B7: System Parameters:
C8: System Frequency | Q8: 50 | S8: Hz
C9: Bus Voltage Level | Q9: 132 | S9: kV
C10: Max. Bus fault level | Q10: 50 | S10: kA
C11: X/R Ratio | Q11: 15 | X11: As per Transco spec page 7/34
C12: MV Bus Voltage Level | Q12: 132 | S12: kV
C13: MV Max. Bus fault level/Switchgear Rating | Q13: 40 | S13: kA | X13: As pre SLD
C14: LV X/R Ratio
B16: Power line parameters:
A17: Assumed Cable: | E17: 3 | F17: C, | G17: CU | H17: HDPE, | J17: 240 | L17: mm2, | N17: 1 | O17: Cables/phase
B18: Cable Details
C20: Positive Sequence- Resistance | O20: R1 | P20: = | Q20: 0.0221 | S20: Ω/Km
C21: Positive Sequence- Reactance | O21: X1 | P21: = | Q21: 0.16 | S21: Ω/Km
C22: Zero Sequence- Resistance | O22: R0 | P22: = | Q22: 0.13 | S22: Ω/Km
C23: Zero Sequence- Reactance | O23: X0 | P23: = | Q23: 0.06 | S23: Ω/Km
C24: Route length | P24: = | Q24: 1.74 | S24: km
C26: Cable +Ve seq. impedence | J26: Z1 | K26: = | L26: =Q20/N17 -> 0.0221 | N26: + j | O26: =Q21/N17 -> 0.16 | Q26: Ω/Km
C27: Cable Zero seq. impedence | J27: Z0 | K27: = | L27: =Q22/N17 -> 0.13 | N27: + j | O27: =Q23/N17 -> 0.06 | Q27: Ω/Km
C28: Total cable +Ve seq. impedence | J28: Z1L | K28: = | L28: =L26*Q24 -> 0.038454 | N28: + j | O28: =O26*Q24 -> 0.2784 | Q28: Ω
C29: Total cable Zero seq. impedence | J29: Z0L | K29: = | L29: =L27*Q24 -> 0.2262 | N29: + j | O29: =O27*Q24 -> 0.1044 | Q29: Ω
B31: Fault Current & Time Constant Calculations:
C32: Maximum HV Busbar fault current | P32: = | Q32: =Q10*1000 -> 50000 | S32: A
C33: HV rating of Busbar | P33: = | Q33: =Q9*1000 -> 132000 | S33: V
C34: Maximum MV Busbar fault current | P34: = | Q34: =Q13*1000 -> 40000 | S34: A
C35: MV rating of Busbar | P35: = | Q35: =Q12*1000 -> 132000 | S35: V
A37: For the above fault condition Source impedance (Zs), considering voltage | P37: = | Q37: 1 | S37: pu
E38: Zs | F38: = | G38: (V | H38: X | I38: =Q37 -> 1 | J38: ) / | K38: (√3 | L38: x | M38: I) | P38: = | Q38: =(Q33*Q37)/(SQRT(3)*Q32) -> 1.5242047 | S38: Ω
E39: Source X / R ratio | F39: = | G39: 2 | H39: x | I39: p | J39: x | K39: f | L39: x | M39: (L/R)
E40: System X/R Ratio | L40: X/R | P40: = | Q40: =Q11 -> 15
E41: System Frequency | L41: f | P41: = | Q41: =Q8 -> 50
C42: Now, | E42: Impedence Angle | L42: øs = | M42: Tan-1(X/R)
E43: Impedence Angle in radians | L43: øs | P43: = | Q43: =ATAN(Q40) -> 1.5042282
E44: Impedence Angle in Degrees | L44: øs | P44: = | Q44: =DEGREES(Q43) -> 86.185925
E46: System Resistance | K46: Rs | L46: =Zs x Cos øs | P46: = | Q46: =Q38*COS(Q43) -> 0.10138859 | S46: W
E47: System Reactance | K47: Xs | L47: =Zs x Sin øs | P47: = | Q47: =Q38*SIN(Q43) -> 1.5208288 | S47: W
...

Sheet BAY1
E22: 132KV CABLE FEEDERS (E03,E07,E10,E14,E15)

Sheet BUP BCU
A1: HITACHI | H1: =Title!H1 -> CT / VT | O1: =Title!O1 -> Contract No. | R1: =Title!R1 -> N-19957.2-DF4W
H2: =Title!H2 -> ADEQUACY CHECK | O2: =Title!O2 -> Date | R2: =Title!R2 -> 46134
H3: =Title!H3 -> 132/33kV SUBSTATION DF4W AT AL DHAFRA AREA | O3: =Title!O3 -> Document No. | R3: =Title!R3 -> -
O4: =Title!O4 -> Revision No. | R4: =Title!R4 -> A
A5: =Title!A5 -> Prep. By | C5: =Title!C5 -> AP | D5: =Title!D5 -> Checked By | G5: =Title!G5 -> RB | H5: BUS SECTION COUPLER | O5: =Title!O5 -> Contractor | R5: =Title!R5 -> HITACHI
B7: T1 | D7: Core1 | H7: (OC+BCPU+FMS) | S7: Connected devices: | T7: REC670
T8: REF650
H9: Tap-1 | J9: Tap-2 | L9: Tap-3
B10: CT Ratio: | H10: 2500 | J10: - | L10: - | N10: / | O10: 1 | P10: A
B11: Class of Accuracy: | H11: 5P20
B12: CT Resistance: | G12: Rct< | H12: 5 | J12: W
B13: Knee Point Voltage: | G13: Vk> | H13: 750 | J13: V | W13: =#REF! -> #REF!
B14: Magnetizing Current: | G14: I0< | H14: 50 | J14: mA at Vk
A16: Other Burdens on same CT core:
B18: Burden of | D18: =T7 -> REC670 | I18: = | J18: ='CT-VT Burdens'!Q104 -> 0.02 | L18: VA | N18: CT internal Burden
B19: Burden of | D19: =T8 -> REF650 | I19: = | J19: ='CT-VT Burdens'!Q104 -> 0.02 | L19: VA | N19: PE | O19: = | P19: In | Q19: x | R19: In | S19: x | T19: Rct
B20: Burden of | D20: =T9 -> 0 | I20: = | L20: VA | O20: = | P20: =O10 -> 1 | Q20: x | R20: =O10 -> 1 | S20: x | T20: =H12 -> 5
B21: Total lead burden | I21: = | J21: ='CT-VT Burdens'!S24 -> 1.0770224 | L21: VA | O21: = | P21: =P20*R20*T20 -> 5 | R21: VA
B22: Total lead + other burden | H22: PL | I22: = | J22: =SUM(J18:J21) -> 1.1170224 | L22: VA
B24: Non-directional instantaneous and definitive time, phase and residual overcurrent protection
B25: Ealreq = | E25: 1.5 | F25: x | G25: Iop | H25: Isr | J25: x | K25: ( | L25: Rct | M25: + | N25: Rl | O25: + | P25: Sr | S25: ) | T25: ---(1)
H26: Ipr | P26: Ir | Q26: x | R26: Ir
C28: 6 times rated primary current concidered
C29: The primary operate value (A) | Q29: Iop | R29: = | S29: =6*S30 -> 15000 | U29: A
C30: The rated primary CT current (A) | Q30: Ipr | R30: = | S30: =H10 -> 2500 | U30: A
C31: The rated secondary CT current (A) | Q31: Isr | R31: = | S31: =O10 -> 1 | U31: A
C32: The rated current of the protection IED (A) | Q32: Ir | R32: = | S32: =O10 -> 1 | U32: A
C33: The secondary resistance of the CT (ohm) | Q33: Rct | R33: = | S33: =H12 -> 5 | U33: ohm
C34: The resistance of the secondary cable and additional load (ohm). | Q34: RL | R34: = | S34: =J22 -> 1.1170224 | U34: ohm
C35: The burden of an IED current input channel (VA) | Q35: SR | R35: = | S35: =J18 -> 0.02 | U35: VA
B37: Ealreq = | D37: 1.5 | E37: x | F37: =S29 -> 15000 | H37: x | I37: =S31 -> 1 | K37: x | L37: ( | M37: =S33 -> 5 | N37: + | O37: =S34 -> 1.1170224 | P37: + | Q37: =S35 -> 0.02 | T37: )
I38: =S30 -> 2500 | Q38: =S32 -> 1 | R38: x | S38: =S32 -> 1
C40: = | D40: =ROUNDUP(D37*F37*(I37/I38)*(M37+O37+(Q37/(Q38*S38))),2) -> 55.24 | F40: V
B49: Non-directional inverse time delayed phase and residual overcurrentprotection
B51: Ealreq = | E51: 20 | F51: x | G51: Iop | H51: Isr | J51: x | K51: ( | L51: Rct | M51: + | N51: Rl | O51: + | P51: Sr | S51: ) | T51: ---(1)
H52: Ipr | P52: Ir | Q52: x | R52: Ir
C54: 1.2 times rated primary current concidered
C55: The primary operate value (A) | Q55: Iop | R55: = | S55: =1.2*S56 -> 3000 | U55: A
C56: The rated primary CT current (A) | Q56: Ipr | R56: = | S56: =H10 -> 2500 | U56: A
C57: The rated secondary CT current (A) | Q57: Isr | R57: = | S57: =O10 -> 1 | U57: A
...

Sheet RED670 IED TEMPLATE
A1: RED 670 IED TEMPLATE
B6: For CT Wiring | Q6: EXAMPLE INPUTS | U6: (UNITS)
B7: Inputs from the USER for CT parameters : | W7: Note: CT requirements for other protection functions are different. Pl. refer to Application Manual
C8: Conductor cross section in mm2 | Q8: A | R8: = | S8: 6 | U8: mm2 | V8: **
C9: Resistance at 200 C | Q9: R20 | R9: = | S9: 3.69 | U9: Ω/km
C10: Specific resistance at 200 C | I10: a is a Constant value which is | Q10: a | R10: = | S10: 0.00393 | U10: K-1
C11: Secondary current of CT | Q11: Is | R11: = | S11: 1 | U11: A
C12: Relay Rated current | Q12: Ir | R12: = | S12: 1 | U12: A
C13: Conductor length in meters ( CT to relay ) | Q13: L | R13: = | S13: 120 | U13: m | V13: ** | W13: Highest Vk required = | AB13: =Q318 -> 1508.5412
C14: Temperature t | I14: t is a Constant value which is | Q14: t | R14: = | S14: 75
B15: CALCULATIONS FOR CT WIRING:
B16: Resistance in Ω/km at t0 C = | H16: R20 [ 1 + a ( t - 200 C ) ]/1000
B17: After Substituting in these above Formula, Multiply by 0.001 for KM to M conversion.
C18: Resistance in ohms/m at 750 C = | Q18: R75 | R18: = | S18: =S9*(1+S10*(75-20))/1000 -> 0.0044875935 | U18: Ω/m
C19: Lead Resistance For CT | O19: RI | Q19: 2RL = 2 x R x L | R19: = | S19: 1.08 | U19: Ω
C20: VA consumption of the connecting leads | O20: PI | Q20: = Is2 X RI | R20: = | S20: =S11*S11*S19 -> 1.08 | U20: VA
Q22: EXAMPLE INPUTS | U22: (UNITS)
B23: For VT Wiring
B24: INPUTS FROM THE USER FOR VT PARAMETERS
B25: Burden of the connecting leads :
C26: Conductor cross section in mm2 | Q26: A | R26: = | S26: 2.5 | U26: mm2 | V26: **
C27: Resistance in W/km at 200 C | Q27: R20 | R27: = | S27: 8.87 | U27: Ω/km
C28: Specific resistance at 200 C | I28: (copper wires) | Q28: a | R28: = | S28: 0.00393 | U28: K-1
C29: Primary Voltage of VT | Q29: Vp | R29: = | S29: 132 / √3 | U29: kV
C30: Secondary Voltage of VT | Q30: Vs | R30: = | S30: 0.11 / √3 | U30: kV
C31: Conductor length For VT | Q31: l | R31: = | S31: 120 | U31: m | V31: **
B32: CALCULATIONS FOR CT WIRING:
B33: Resistance in Ω/km at t0 C R75 = | I33: R20 [ 1 + a ( t - 200 C ) ]/1000
C34: Resistance in W/km at 750 C = | R34: = | S34: =S27*(1+S28*(75-20)) -> 10.78725 | U34: Ω/km
C35: Resistance in W/m at 750 C = | Q35: R75 | R35: = | S35: =S34/1000 -> 0.01078725 | U35: Ω/m
C36: Lead Resistance of the current loop from the VT to Relay | O36: RI | Q36: 2RL = 2 x R x l | R36: = | S36: =2*S35*S31 -> 2.5889401 | U36: Ω
A38: The above CT Wiring and VT Wiring calculations is done for all the IEDs. SO, The inputs will be same for all IEDs in each bay. The formula will be same for all the bays. But the inputs might differ for each bays.
B43: IED BURDENS FOR CT VT CALCULATION | Q43: CT at 1A | S43: VT at 110V
A44: Relion 670/650 series Relays Such as (RED670,REC670,REB650,RET670) | O44: IED 670/650 | Q44: 0.02 | S44: 0.02 | U44: VA
A46: SIEMENS Siprotec Relay | M46: 7SLJ86 | Q46: 0.01 | S46: 0.01
A47: All relion series 670 and 650 IEDs will have 0.02 burden for both CT and VT
A48: The above values are the IED burden values. These are Standard values for Each IEDs
A50: INPUTS FROM USERS | O50: EXAMPLE INPUTS
B51: System Parameters:
C52: System Frequency | Q52: 50 | S52: Hz
...

Sheet 7SJ85 IED TEMPLATE
H2: 7SJ85 IED TEMPLATE
B5: For CT Wiring | Q5: EXAMPLE INPUTS | U5: (UNITS) | X5: For CT Wiring | AM5: EXAMPLE INPUTS | AQ5: (UNITS)
B6: Inputs from the USER for CT parameters : | X6: Inputs from the USER for CT parameters :
C7: Conductor cross section in mm2 | Q7: A | R7: = | S7: 6 | U7: mm2 | V7: ** | Y7: Conductor cross section in mm2 | AM7: A | AN7: = | AO7: 6 | AQ7: mm2 | AR7: **
C8: Resistance at 200 C | Q8: R20 | R8: = | S8: 3.69 | U8: Ω/km | Y8: Resistance at 200 C | AM8: R20 | AN8: = | AO8: 3.69 | AQ8: Ω/km
C9: Specific resistance at 200 C | I9: a is a Constant value which is | Q9: a | R9: = | S9: 0.00393 | U9: K-1 | Y9: Specific resistance at 200 C | AE9: a is a Constant value which is | AM9: a | AN9: = | AO9: 0.00393 | AQ9: K-1
C10: Secondary current of CT | Q10: Is | R10: = | S10: 1 | U10: A | Y10: Secondary current of CT | AM10: Is | AN10: = | AO10: 1 | AQ10: A
C11: Relay Rated current | Q11: Ir | R11: = | S11: 1 | U11: A | Y11: Relay Rated current | AM11: Ir | AN11: = | AO11: 1 | AQ11: A
C12: Conductor length in meters ( CT to relay ) | Q12: L | R12: = | S12: 120 | U12: m | V12: ** | Y12: Conductor length in meters ( CT to relay ) | AM12: L | AN12: = | AO12: 120 | AQ12: m | AR12: **
C13: Temperature t | I13: t is a Constant value which is | Q13: t | R13: = | S13: 75 | Y13: Temperature t | AE13: t is a Constant value which is | AM13: t | AN13: = | AO13: 75
B14: CALCULATIONS FOR CT WIRING: | X14: CALCULATIONS FOR CT WIRING:
B15: Resistance in Ω/km at t0 C = | H15: R20 [ 1 + a ( t - 200 C ) ]/1000 | X15: Resistance in Ω/km at t0 C = | AD15: R20 [ 1 + a ( t - 200 C ) ]/1000
B16: After Substituting in these above Formula, Multiply by 0.001 for KM to M conversion. | X16: After Substituting in these above Formula, Multiply by 0.001 for KM to M conversion. | AT16: =AO12*(1+AO13*(75-20)) -> 495120 | AV16: 5.61
C17: Resistance in ohms/m at 750 C = | Q17: R75 | R17: = | S17: =S8*(1+S9*(75-20))/1000 -> 0.0044875935 | U17: Ω/m | Y17: Resistance in ohms/m at 750 C = | AM17: R75 | AN17: = | AO17: =AO8*(1+AO9*(75-20))/1000 -> 0.0044875935 | AQ17: Ω/m
C18: Lead Resistance For CT | O18: RI | Q18: 2RL = 2 x R x L | R18: = | S18: 1.08 | U18: Ω | Y18: Lead Resistance For CT | AK18: RI | AM18: 2RL = 2 x R x L | AN18: = | AO18: 1.08 | AQ18: Ω
C19: VA consumption of the connecting leads | O19: PI | Q19: = Is2 X RI | R19: = | S19: =S10*S10*S18 -> 1.08 | U19: VA | Y19: VA consumption of the connecting leads | AK19: PI | AM19: = Is2 X RI | AN19: = | AO19: =AO10*AO10*AO18 -> 1.08 | AQ19: VA
Q21: EXAMPLE INPUTS | U21: (UNITS) | AM21: EXAMPLE INPUTS | AQ21: (UNITS) | AT21: This Current Must be Linked Later to Fault Setting
B22: For VT Wiring | X22: For VT Wiring
B23: INPUTS FROM THE USER FOR VT PARAMETERS | X23: INPUTS FROM THE USER FOR VT PARAMETERS
B24: Burden of the connecting leads : | X24: Burden of the connecting leads :
C25: Conductor cross section in mm2 | Q25: A | R25: = | S25: 2.5 | U25: mm2 | V25: ** | Y25: Conductor cross section in mm2 | AM25: A | AN25: = | AO25: 2.5 | AQ25: mm2 | AR25: **
C26: Resistance in W/km at 200 C | Q26: R20 | R26: = | S26: 8.87 | U26: Ω/km | Y26: Resistance in W/km at 200 C | AM26: R20 | AN26: = | AO26: 8.87 | AQ26: Ω/km
C27: Specific resistance at 200 C | I27: (copper wires) | Q27: a | R27: = | S27: 0.00393 | U27: K-1 | Y27: Specific resistance at 200 C | AE27: (copper wires) | AM27: a | AN27: = | AO27: 0.00393 | AQ27: K-1
C28: Primary Voltage of VT | Q28: Vp | R28: = | S28: 132 / √3 | U28: kV | Y28: Primary Voltage of VT | AM28: Vp | AN28: = | AO28: 132 / √3 | AQ28: kV
C29: Secondary Voltage of VT | Q29: Vs | R29: = | S29: 0.11 / √3 | U29: kV | Y29: Secondary Voltage of VT | AM29: Vs | AN29: = | AO29: 0.11 / √3 | AQ29: kV
C30: Conductor length For VT | Q30: l | R30: = | S30: 120 | U30: m | V30: ** | Y30: Conductor length For VT | AM30: l | AN30: = | AO30: 120 | AQ30: m | AR30: **
B31: CALCULATIONS FOR CT WIRING: | X31: CALCULATIONS FOR CT WIRING:
B32: Resistance in Ω/km at t0 C R75 = | I32: R20 [ 1 + a ( t - 200 C ) ]/1000 | X32: Resistance in Ω/km at t0 C R75 = | AE32: R20 [ 1 + a ( t - 200 C ) ]/1000
C33: Resistance in W/km at 750 C = | R33: = | S33: =S26*(1+S27*(75-20)) -> 10.78725 | U33: Ω/km | Y33: Resistance in W/km at 750 C = | AN33: = | AO33: =AO26*(1+AO27*(75-20)) -> 10.78725 | AQ33: Ω/km
C34: Resistance in W/m at 750 C = | Q34: R75 | R34: = | S34: =S33/1000 -> 0.01078725 | U34: Ω/m | Y34: Resistance in W/m at 750 C = | AM34: R75 | AN34: = | AO34: =AO33/1000 -> 0.01078725 | AQ34: Ω/m
C35: Lead Resistance of the current loop from the VT to Relay | O35: RI | Q35: 2RL = 2 x R x l | R35: = | S35: =2*S34*S30 -> 2.5889401 | U35: Ω | Y35: Lead Resistance of the current loop from the VT to Relay | AK35: RI | AM35: 2RL = 2 x R x l | AN35: = | AO35: =2*AO34*AO30 -> 2.5889401 | AQ35: Ω
A37: The above CT Wiring and VT Wiring calculations is done for all the IEDs. SO, The inputs will be same for all IEDs in each bay. The formula will be same for all the bays. But the inputs might differ for each bays. | W37: The above CT Wiring and VT Wiring calculations is done for all the IEDs. SO, The inputs will be same for all IEDs in each bay. The formula will be same for all the bays. But the inputs might differ for each bays.
B42: IED BURDENS FOR CT VT CALCULATION | Q42: CT at 1A | S42: VT at 110V | X42: IED BURDENS FOR CT VT CALCULATION | AM42: CT at 1A | AO42: VT at 110V
A43: Relion 670/650 series Relays Such as (RED670,REC670,REB650,RET670) | O43: IED 670/650 | Q43: 0.02 | S43: 0.02 | U43: VA | W43: Relion 670/650 series Relays Such as (RED670,REC670,REB650,RET670) | AK43: IED 670/650 | AM43: 0.02 | AO43: 0.02 | AQ43: VA
A45: SIEMENS Siprotec Relay | M45: 7SLJ86 | Q45: 0.01 | S45: 0.01 | W45: SIEMENS Siprotec Relay | AI45: 7SLJ86 | AM45: 0.01 | AO45: 0.01
A46: All relion series 670 and 650 IEDs will have 0.02 burden for both CT and VT | W46: All relion series 670 and 650 IEDs will have 0.02 burden for both CT and VT
A47: The above values are the IED burden values. These are Standard values for Each IEDs | W47: The above values are the IED burden values. These are Standard values for Each IEDs
A49: INPUTS FROM USERS | O49: EXAMPLE INPUTS | W49: INPUTS FROM USERS | AK49: EXAMPLE INPUTS
B50: System Parameters: | X50: System Parameters:
C51: System Frequency | Q51: 50 | S51: Hz | Y51: System Frequency | AM51: 50 | AO51: Hz
...

Sheet TR. MAIN-2 MF 
A1: HITACHI | H1: =[3]Title!H1 -> CT / VT | O1: =Title!O1 -> Contract No. | R1: =Title!R1 -> N-19957.2-DF4W
H2: =[3]Title!H2 -> CALCULATION | O2: =Title!O2 -> Date | R2: =Title!R2 -> 46134
H3: =Title!H3 -> 132/33kV SUBSTATION DF4W AT AL DHAFRA AREA | O3: =Title!O3 -> Document No. | R3: =Title!R3 -> -
O4: =Title!O4 -> Revision No. | R4: =Title!R4 -> A
A5: =[3]Title!A5 -> Prep. By | C5: =[3]Title!C5 -> PK | D5: =[3]Title!D5 -> Checked By | G5: =[3]Title!G5 -> RN | H5: 132kV_100MVA TR. FEEDERS | O5: =Title!O5 -> Contractor | R5: =Title!R5 -> HITACHI
B7: T1 | D7: Core2 | G7: (Multi Func. Trans. Prtn + FMS + HV REF) | S7: Connected devices: | T7: 7UT85
H9: Tap-1 | J9: Tap-2 | L9: Tap-3
B10: CT Ratio: | H10: 3200 | J10: 600 | L10: - | N10: / | O10: 1 | P10: A
B11: Class of Accuracy: | H11: PX
B12: CT Resistance: | G12: Rct< | H12: 16 | J12: W
B13: Knee Point Voltage: | G13: Vk> | H13: 1600 | J13: V | W13: Highest Vk required = | AB13: =D57 -> 107.36
B14: Magnetizing Current: | G14: I0< | H14: 10 | J14: mA at Vk
A16: Other Burdens on same CT core:
B18: Burden of | D18: =T7 -> 7UT85 | H18: Sr' | I18: = | J18: ='CT-VT Burdens'!Q119 -> 0.1 | L18: VA
B19: Burden of | D19: =T8 -> 0 | I19: = | L19: VA
B20: Burden of | D20: =T9 -> 0 | I20: = | L20: VA
B21: Total lead burden | H21: Sl' | I21: = | J21: ='CT-VT Burdens'!S24 -> 1.0770224 | L21: VA
B22: Total lead + other burden | H22: Sl | I22: = | J22: =J19+J21 -> 1.0770224 | L22: VA
B24: Resisitance of the relay: | M24: Lead + Other resisitance connected
B25: Rr | C25: = | D25: Sr' | E25: / ( | F25: Ir | G25: x | H25: Ir | I25: ) | M25: Rl | N25: = | O25: Sl | P25: / ( | Q25: Isn | R25: x | S25: Isn | T25: )
C26: = | D26: =J18 -> 0.1 | E26: / ( | F26: =S53 -> 1 | G26: x | H26: =S53 -> 1 | I26: ) | N26: = | O26: =J22 -> 1.0770224 | P26: / ( | Q26: =O10 -> 1 | R26: x | S26: =O10 -> 1 | T26: )
C27: = | D27: =D26/(F26*H26) -> 0.1 | F27: W | N27: = | O27: =O26/(Q26*S26) -> 1.0770224 | Q27: W
B29: Hence, Total Burden connected to CT core, Rb' | L29: = | M29: =D27 -> 0.1 | O29: + | P29: =O27 -> 1.0770224 | R29: = | S29: =M29+P29 -> 1.1770224 | U29: W
A30: Power Transformer Data:
B31: Power Rating | N31: = | O31: 100 | Q31: MVA
B32: Percentage Impedance | N32: = | O32: 25 | Q32: %
B33: HV Rated Voltage, | M33: Un1 | N33: = | O33: 132 | Q33: kV
A35: Transformer Full load current | H35: Int | I35: = | J35: MVA | L35: x | M35: 1000 | N35: / | O35: √3 | P35: x | Q35: Un1 | R35: )
I36: = | J36: =O31 -> 100 | L36: x | M36: 1000 | N36: / | O36: √3 | P36: x | Q36: =O33 -> 132 | R36: )
I37: = | J37: =(O31*1000)/(SQRT(3)*O33) -> 437.38657 | L37: A
A38: The internal fault current shall be 50kA.
A40: Internal Fault Current (LV Side) | N40: = | O40: 50000 | Q40: A
B42: Vk | C42: ³ | G42: 0.4 | H42: x | I42: Isccmax (int. fault) | N42: x ( | O42: Rct | P42: + | Q42: Rbc | R42: ) x | S42: Isr | U42: ---(1)
I43: Ipr
B47: Rated primary current of the current transformer | P47: Ipr | R47: = | S47: =H10 -> 3200 | U47: A
B48: CT Internal Resistance | P48: Rct | R48: = | S48: =H12 -> 16 | U48: W
B49: Burden of CT Leads and burden of relay | P49: Rbc | R49: = | S49: =S29 -> 1.1770224 | U49: W
B50: Rated secondary current of the current transformer | P50: Isn | R50: = | S50: =O10 -> 1 | U50: A
B51: Max fault current at close-in fault | P51: Isccmax (int. fault) | R51: = | S51: =O40 -> 50000 | U51: A
B52: Transformer nominal current | P52: Ino | R52: = | S52: =J37 -> 437.38657 | U52: A
...

Sheet CABLE MAIN-2
B7: T1 | D7: Core2 | F7: Main-1 | H7: (Line Diff&Dist.+FMS/PMU) | S7: Connected devices: | T7: 7SL86
H9: Tap-1 | J9: Tap-2 | L9: Tap-3
B10: CT Ratio: | H10: 3200 | J10: 1800 | L10: - | N10: / | O10: 1 | P10: A
B11: Class of Accuracy: | H11: ='[3]RED670_2.2C42-PX'!H11:I11 -> PX
B12: CT Resistance: | G12: Rct < | H12: 9.8 | J12: W
B13: Knee Point Voltage: | G13: Vk > | H13: 2000 | J13: V | W13: Highest Vk required = | AB13: =Q102 -> 598.03947
B14: Magnetizing Current: | G14: I0< | H14: 10 | J14: mA at Vk
A16: Other Burdens on same CT core:
B18: Burden of | D18: =T7 -> 7SL86 | H18: Sr' | I18: = | J18: ='CT-VT Burdens'!Q118 -> 0.1 | L18: VA
B19: Burden of | D19: =T8 -> 0 | I19: = | L19: VA
B20: Burden of | D20: =T9 -> 0 | I20: = | L20: VA
B21: Total lead burden | I21: = | J21: ='CT-VT Burdens'!S24 -> 1.0770224 | L21: VA
B22: Total lead + other burden | H22: Sl | I22: = | J22: =SUM(J18:K21) -> 1.1770224 | L22: VA
B24: Resisitance of the relay: | M24: Lead + Other resisitance connected
B25: Rr | C25: = | D25: Sr' | E25: / ( | F25: Ir | G25: x | H25: Ir | I25: ) | M25: Rl | N25: = | O25: Sl | P25: / ( | Q25: Isr | R25: x | S25: Isr | T25: )
C26: = | D26: =J18 -> 0.1 | E26: / ( | F26: ='[3]CT-VT Burdens'!S18 -> 1 | G26: x | H26: ='[3]CT-VT Burdens'!S18 -> 1 | I26: ) | N26: = | O26: =J21 -> 1.0770224 | P26: / ( | Q26: =O10 -> 1 | R26: x | S26: =O10 -> 1 | T26: )
C27: = | D27: =D26/(F26*H26) -> 0.1 | F27: W | N27: = | O27: =O26/(Q26*S26) -> 1.0770224 | Q27: W
B29: Hence, Total Burden connected to CT core, Rba | L29: = | M29: =D27 -> 0.1 | O29: + | P29: =O27 -> 1.0770224 | R29: = | S29: =M29+P29 -> 1.1770224 | U29: W
A30: CT req. as per Siprotec Manual page# 1936 and 1937 ( Refer Annexure-H) for 7SL86 with Diff + Dist. functions as follows:
A32: Diff. function:
B33: Internal Fault
B34: Ek | C34: ³ | G34: 0.5 | H34: x | I34: Isc_Int | N34: x ( | O34: Rct | P34: + | Q34: Rba | R34: ) x | S34: Isr | U34: ---(1)
I35: 1.25 | K35: x | L35: Ipr
B36: External Fault
B37: Ek | C37: ³ | G37: 1.2 | H37: x | I37: Isc_Ext | N37: x ( | O37: Rct | P37: + | Q37: Rba | R37: ) x | S37: Isr | U37: ---(2)
I38: 1.25 | K38: x | L38: Ipr
A39: Distance function:
B40: For Close-in faults:
B41: Ek | C41: ³ | G41: a | H41: x | I41: Isc_A | N41: x ( | O41: Rct | P41: + | Q41: Rba | R41: ) x | S41: Isr | U41: ---(3)
I42: 1.25 | K42: x | L42: Ipr
B43: For Zone-1 end faults:
B44: Ek | C44: ³ | G44: b | H44: x | I44: Isc_B | N44: x ( | O44: Rct | P44: + | Q44: Rba | R44: ) x | S44: Isr | U44: ---(4)
I45: 1.25 | J45: 1.3 | K45: x | L45: Ipr
B47: CT Primary Current | P47: Ipr | R47: = | S47: =H10 -> 3200 | U47: A
B48: CT Internal Resistance | P48: Rct | R48: = | S48: =H12 -> 9.8 | U48: W
B49: Burden of CT Leads and burden of relay | P49: Rba | R49: = | S49: =S29 -> 1.1770224 | U49: W
B50: Rated CT Secondary Current | P50: Isr | R50: = | S50: =O10 -> 1 | U50: A
B51: Max fault current for Through fault | P51: Isc_A / Isc_Ext | R51: = | S51: ='Parameters & Fault Cal. (4)'!M71 -> 42229.804 | U51: A
B52: Primary time constant for close in fault | P52: tp | R52: = | S52: ='Parameters & Fault Cal. (4)'!Q102 -> 27.369568
B53: Max Phase through fault current at Zone-1 end fault | P53: Isc_B (zone1 end phase fault) | R53: = | S53: ='Parameters & Fault Cal. (4)'!M112 -> 43584.822 | U53: A
...

Sheet BCU+AMMETER
A1: HITACHI | H1: =Title!H1 -> CT / VT | O1: =Title!O1 -> Contract No. | R1: =Title!R1 -> N-19957.2-DF4W
H2: =Title!H2 -> ADEQUACY CHECK | O2: =Title!O2 -> Date | R2: =Title!R2 -> 46134
H3: =Title!H3 -> 132/33kV SUBSTATION DF4W AT AL DHAFRA AREA | O3: =Title!O3 -> Document No. | R3: =Title!R3 -> -
O4: =Title!O4 -> Revision No. | R4: =Title!R4 -> A
A5: =Title!A5 -> Prep. By | C5: =Title!C5 -> AP | D5: =Title!D5 -> Checked By | G5: =Title!G5 -> RB | H5: 132KV CABLE FEEDERS | O5: =Title!O5 -> Contractor | R5: =Title!R5 -> HITACHI
B6: For CT Wiring
B7: Burden of the connecting leads :
C8: Conductor cross section in mm2 | Q8: A | R8: = | S8: 6 | T8: CP-L96A | U8: mm2 | V8: **
C9: Resistance in W/km at 200 C | Q9: R20 | R9: = | S9: 3.69 | U9: Ω/km
C10: Specific resistance at 200 C | I10: (copper wires) | Q10: a | R10: = | S10: 0.00393 | U10: K-1
B12: Resistance in Ω/km at t0 C = | H12: R20 [ 1 + a ( t - 200 C ) ]
C13: Resistance in ohms/km at 750 C = | R13: = | S13: =S9*(1+S10*(75-20)) -> 4.4875935 | U13: Ω/km | W13: =J46 -> 0
C14: Resistance in ohms/m at 750 C = | Q14: R | R14: = | S14: =S13/1000 -> 0.0044875935 | U14: Ω/m
C15: Secondary current of CT | Q15: Is | R15: = | S15: 1 | U15: A
C16: Relay Rated current | Q16: Ir | R16: = | S16: 1 | U16: A
AC18: rec670 | AE18: 100A for 1 S
C19: Conductor length in meters ( CT to relay ) | Q19: l | R19: = | S19: 120 | U19: m | V19: **
C20: Lead Resistance from the CT to Relay | Q20: RL =R x l | R20: = | S20: =S14*S19 -> 0.53851122 | U20: Ω
C21: Lead Resistance of the current loop from the CT to Relay | Q21: 2RL = 2 x R x l | R21: = | S21: =2*S14*S19 -> 1.0770224 | U21: Ω
C22: VA consumption of the connecting leads | Q22: Pl = Is2 x Rl | R22: = | S22: =S15*S15*S21 -> 1.0770224 | U22: VA
B25: For VT Wiring
B26: Burden of the connecting leads :
C27: Conductor cross section in mm2 | Q27: A | R27: = | S27: 2.5 | U27: mm2 | V27: **
C28: Resistance in W/km at 200 C | Q28: R20 | R28: = | S28: 8.87 | U28: Ω/km
C29: Specific resistance at 200 C | I29: (copper wires) | Q29: a | R29: = | S29: 0.00393 | U29: K-1
B31: Resistance in Ω/km at t0 C = | I31: R20 [ 1 + a ( t - 200 C ) ]
C32: Resistance in W/km at 750 C = | R32: = | S32: =S28*(1+S29*(75-20)) -> 10.78725 | U32: Ω/km
C33: Resistance in W/m at 750 C = | Q33: R | R33: = | S33: =S32/1000 -> 0.01078725 | U33: Ω/m
C34: Primary Voltage of VT | Q34: Vp | R34: = | S34: 132 / √3 | U34: kV
C35: Secondary Voltage of VT | Q35: Vs | R35: = | S35: 0.11 / √3 | U35: kV
C38: Conductor length in meters ( VT to relay ) | Q38: l | R38: = | S38: 120 | U38: m | V38: **
C39: Lead Resistance from the VT to Relay | Q39: RL =R x l | R39: = | S39: =S33*S38 -> 1.2944701 | U39: Ω
C40: Lead Resistance of the current loop from the VT to Relay | Q40: 2RL = 2 x R x l | R40: = | S40: =2*S33*S38 -> 2.5889401 | U40: Ω
A42: The above CT Wiring and VT Wiring calculations is done for all the IEDs. The formula will be same for all the bays. But the inputs might differ for each bays.
B46: CT/VT Burden of Connected Devices (per phase): | Q46: CT at 1A | S46: VT at 110V
A47: Relion 670/650 series Relays Such as (RED670,REC670,REB650,RET670) | O47: IED 670/650 | Q47: 0.02 | S47: 0.02 | U47: VA
A49: All relion series 670 and 650 IEDs will have 0.02 burden for both CT and VT
C50: Busbar Protection Relay | O50: REB500 | Q50: 0.01 | S50: 0.15 | U50: VA
C51: ABB REx 52x Relays | O51: REJ525/REJ521/REX521 | Q51: 0.1 | S51: 0.5 | U51: VA
C52: ABB Relion 650 series Relays | O52: IED650 | Q52: 0.02 | S52: 0.02 | U52: VA
...

Sheet MAIN-1 BBP
A1: HITACHI | H1: =Title!H1 -> CT / VT | O1: =Title!O1 -> Contract No. | R1: =Title!R1 -> N-19957.2-DF4W
H2: =Title!H2 -> ADEQUACY CHECK | O2: =Title!O2 -> Date | R2: =Title!R2 -> 46134
H3: =Title!H3 -> 132/33kV SUBSTATION DF4W AT AL DHAFRA AREA | O3: =Title!O3 -> Document No. | R3: =Title!R3 -> -
O4: =Title!O4 -> Revision No. | R4: =Title!R4 -> A
A5: =Title!A5 -> Prep. By | C5: =Title!C5 -> AP | D5: =Title!D5 -> Checked By | G5: =Title!G5 -> RB | H5: 132KV CABLE FEEDERS | O5: =Title!O5 -> Contractor | R5: =Title!R5 -> HITACHI
B7: T1 | D7: Core4 | H7: (Low Imp. Busbar) | S7: Connected devices: | T7: 7SS522
T8: 6MU85
H9: Tap-1 | J9: Tap-2 | L9: Tap-3
B10: CT Ratio: | H10: 3200 | J10: 2000 | N10: / | O10: 1 | P10: A
B11: Class of Accuracy: | H11: PX
B12: CT Resistance: | G12: Rct< | H12: 8 | J12: W
B13: Knee Point Voltage: | G13: Vk> | H13: 900 | J13: V | W13: =H74 -> Suitably Dimensioned
B14: Magnetizing Current: | G14: I0< | H14: 10 | J14: mA at Vk
A16: Other Burdens on same CT core:
B18: Burden of | D18: =T7 -> 7SS522 | I18: = | J18: ='CT-VT Burdens'!Q153 -> 0.1 | L18: VA
B19: Burden of | D19: =T8 -> 6MU85 | I19: = | J19: ='CT-VT Burdens'!Q154 -> 0.1 | L19: VA
B20: Burden of | D20: =T9 -> 0 | I20: = | L20: VA
B21: Total lead burden | I21: = | J21: ='CT-VT Burdens'!S24 -> 1.0770224 | L21: VA
B22: Total lead + other burden | H22: PL | I22: = | J22: =SUM(J18:J21) -> 1.2770224 | L22: VA
C25: Max primary fundamental frequency fault current (ext. fault) | Q25: Issc max | R25: = | S25: ='Parameters & Fault Cal. (4)'!Q32 -> 50000 | U25: A
C26: CT Primary Current | Q26: Ipn | R26: = | S26: =H10 -> 3200 | U26: A
C27: CT Secondary Current | Q27: Isn | R27: = | S27: =O10 -> 1 | U27: A
C28: Burden of CT Leads and other connected devices | Q28: PL | R28: = | S28: =J22 -> 1.2770224 | U28: VA
C29: Resistive burden of CT Leads and other connected devices | Q29: Rb' | R29: = | S29: =J22/S27*S27 -> 1.2770224 | U29: W
C30: Ktd for stabilizing factor, k >= 0.5 | Q30: Ktd | R30: = | S30: 0.5
A33: The CT requirement is as follows:
A35: Criteria I
B36: Vk | D36: >= | E36: Ktd | F36: x | G36: Issc max | K36: x ( | L36: Rct | N36: + | O36: Rb' | Q36: ) x | R36: Isn
G37: 1.3 | H37: x | I37: Ipn
D39: = | E39: =S30 -> 0.5 | F39: x | G39: =S25 -> 50000 | K39: x ( | L39: =H12 -> 8 | N39: + | O39: =S29 -> 1.2770224 | Q39: ) x | R39: =S27 -> 1
G40: 1.3 | H40: x | I40: =S26 -> 3200
D42: = | E42: =E39*(G39/(G40*I40))*(L39+O39)*R39 -> 55.751337
A47: Criteria II
B48: Vk | D48: >= | E48: 100 | G48: x ( | H48: Rct | J48: + | K48: Rb' | M48: ) x | N48: Isn
E49: 1.3
D51: >= | E51: 100 | G51: x ( | H51: =H12 -> 8 | J51: + | K51: =S29 -> 1.2770224 | M51: ) x | N51: =S27 -> 1
E52: 1.3
D54: >= | E54: =(E51/E52)*(H51+K51)*N51 -> 713.61711
A63: Adequacy Check
B65: Criteria I
...

Sheet BUP BCU(1)
A1: HITACHI | H1: =[4]Title!H1 -> CT / VT | O1: =Title!O1 -> Contract No. | R1: =Title!R1 -> N-19957.2-DF4W
H2: =[4]Title!H2 -> ADEQUACY CHECK | O2: =Title!O2 -> Date | R2: =Title!R2 -> 46134
H3: =Title!H3 -> 132/33kV SUBSTATION DF4W AT AL DHAFRA AREA | O3: =Title!O3 -> Document No. | R3: =Title!R3 -> -
O4: =Title!O4 -> Revision No. | R4: =Title!R4 -> A
A5: =[4]Title!A5 -> Prep. By | C5: =[4]Title!C5 -> AK | D5: =Title!D5 -> Checked By | G5: =[4]Title!G5 -> LN | H5: 132KV CABLE FEEDER | O5: =Title!O5 -> Contractor | R5: =[4]Title!R5 -> HITACHI ENERGY
B7: T1 | D7: Core1 | S7: Connected devices: | T7: REF650
T8: REC670
H9: Tap-1 | J9: Tap-2 | L9: Tap-3
B10: CT Ratio: | H10: 2500 | J10: - | L10: - | N10: / | O10: 1 | P10: A
B11: Class of Accuracy: | H11: 5P20
B12: CT Resistance: | G12: Rct< | H12: 5 | J12: W
B13: Knee Point Voltage: | G13: Vk> | J13: V | W13: =G61 -> Suitably Dimentioned
B14: Magnetizing Current: | G14: I0< | J14: mA at Vk
A16: Other Burdens on same CT core:
B18: Burden of | D18: =T7 -> REF650 | I18: = | J18: ='CT-VT Burdens'!Q104 -> 0.02 | L18: VA | N18: CT internal Burden
B19: Burden of | D19: =T8 -> REC670 | I19: = | J19: ='CT-VT Burdens'!Q104 -> 0.02 | L19: VA
B20: Burden of | D20: =T9 -> 0 | I20: = | L20: VA | N20: PE | O20: = | P20: In | Q20: x | R20: In | S20: x | T20: Rct
B21: Total lead burden | I21: = | J21: ='CT-VT Burdens'!S24 -> 1.0770224 | L21: VA | O21: = | P21: =O10 -> 1 | Q21: x | R21: =O10 -> 1 | S21: x | T21: =H12 -> 5
B22: Total lead + other burden | H22: PL | I22: = | J22: =SUM(J18:J21) -> 1.1170224 | L22: VA | O22: = | P22: =P21*R21*T21 -> 5 | R22: VA
A24: The design values according to BS can be approximately transferred in to IEC60044 Standard using the following formula: | W24: The design values according to BS can be approximately transferred in to IEC60044 Standard using the following formula:
C27: Vk | D27: = | E27: ( ( | F27: PN | G27: + | H27: PE | I27: ) x | J27: n | K27: ) / ( | L27: In | M27: x | N27: 1.3 | O27: )
A28: Or
C29: PN | D29: = | E29: ( ( | F29: 1.3 | G29: x | H29: Vk | J29: x | K29: In | L29: ) / | M29: n | N29: ) - | O29: PE
C31: Max through fault current at close in fault | Q31: Itkmax | R31: = | S31: ='Parameters & Fault Cal. (4)'!Q32 -> 50000 | U31: A
C32: CT Primary Current, | Q32: Ipn | R32: = | S32: =H10 -> 2500 | U32: A
C33: Rated Knee Point Voltage, | Q33: Vk | R33: = | S33: =H13 -> 0 | U33: V
C34: Internal Burden, | Q34: PE | R34: = | S34: =P22 -> 5 | U34: VA
C35: Burden of CT Leads and burden of connected devices | Q35: PL | R35: = | S35: =J22 -> 1.1170224 | U35: VA
C36: Rated Secondary Current, | Q36: In | R36: = | S36: =O10 -> 1 | U36: A
C37: CT Accuracy Limiting Factor | Q37: n | R37: = | S37: 20
C38: Rated CT Burden | Q38: PN | R38: = | S38: 30
C45: PN | D45: = | E45: ( ( | F45: 1.3 | G45: x | H45: Vk | J45: x | K45: In | L45: ) / | M45: n | N45: ) - | O45: PE
D46: = | E46: ( ( | F46: 1.3 | G46: x | H46: =S33 -> 0 | J46: x | K46: =S36 -> 1 | L46: ) / | M46: =S37 -> 20 | N46: ) - | O46: =S34 -> 5
D47: = | E47: =((F46*H46)/(K46*M46))-O46 -> -5 | G47: VA
E51: Required Kssc' | F51: = | G51: Itkmax | I51: / | J51: Ipn
F52: = | G52: =S31 -> 50000 | I52: / | J52: =S32 -> 2500
F53: = | G53: =G52/J52 -> 20
E55: Available (effective) Kssc' | F55: = | G55: n | H55: x ( ( | I55: PE | J55: + | K55: PN | L55: ) / ( | M55: PE | N55: + | O55: PL | P55: )
F56: = | G56: =S37 -> 20 | H56: x ( ( | I56: =S34 -> 5 | J56: + | K56: =S38 -> 30 | L56: ) / ( | M56: =S34 -> 5 | N56: + | O56: =S35 -> 1.1170224 | P56: )
F57: = | G57: =G56*((I56+K56)/(M56+O56)) -> 114.43476
...

Sheet BBP P743(1)
A1: HITACHI | H1: =[5]Title!H1 -> CT / VT | O1: =[5]Title!O1 -> Contract No. | R1: =Title!R1 -> N-19957.2-DF4W
H2: =[5]Title!H2 -> ADEQUACY CHECK | O2: =[5]Title!O2 -> Date | R2: =Title!R2 -> 46134
H3: =Title!H3 -> 132/33kV SUBSTATION DF4W AT AL DHAFRA AREA | O3: =[5]Title!O3 -> Document No. | R3: =Title!R3 -> -
O4: =[5]Title!O4 -> Revision No. | R4: =Title!R4 -> A
A5: =[5]Title!A5 -> Prep. By | C5: =[5]Title!C5 -> AP | D5: =[5]Title!D5 -> Checked By | G5: =[5]Title!G5 -> RB | H5: BUS SECTION COUPLER | O5: =[5]Title!O5 -> Contractor | R5: =Title!R5 -> HITACHI
B7: T1 | D7: Core2 | S7: Connected devices: | T7: P743
H9: Tap-1 | J9: Tap-2 | L9: Tap-3
B10: CT Ratio: | H10: 2500 | J10: - | L10: - | N10: / | O10: 1 | P10: A
B11: Class of Accuracy: | H11: PX-B
B12: CT Resistance: | G12: Rct< | H12: 5 | J12: W
B13: Knee Point Voltage: | G13: Vk> | H13: 750 | J13: V | W13: =H59 -> Suitably Dimentioned
B14: Magnetizing Current: | G14: I0< | H14: 60 | J14: mA at Vk
A16: Other Burdens on same CT core:
B18: Burden of | D18: =T7 -> P743 | I18: = | J18: ='CT-VT Burdens'!Q159 -> 0.1 | L18: VA
B19: Burden of | D19: =T8 -> 0 | I19: = | L19: VA
B20: Burden of | D20: =T9 -> 0 | I20: = | L20: VA
B21: Total lead burden | I21: = | J21: ='CT-VT Burdens'!S24 -> 1.0770224 | L21: VA
B22: Total lead + other burden | H22: PL | I22: = | J22: =SUM(J18:J21) -> 1.1770224 | L22: VA
C24: Max primary fault current (same for all feeders) | Q24: IFmax | R24: = | S24: ='Parameters & Fault Cal. (4)'!Q10 *1000 -> 50000 | U24: A
C25: CT Primary Current | Q25: Ipn | R25: = | S25: =H10 -> 2500 | U25: A
C26: Max secondary fault current (same for all feeders) | Q26: Ifmax | R26: = | S26: =S24/S25*O10 -> 20 | U26: A
C27: Resistive burden of CT Leads (2Rl) and other connected devices | Q27: Rb' | R27: = | S27: =J22/O10*O10 -> 1.1770224 | U27: W
C28: Max primary contribution from a feeder to an internal fault | Q28: IFmax int | R28: = | S28: =20*S25 -> 50000 | U28: A
C29: Max secondary contribution from a feeder to an internal fault | Q29: Ifmax int | R29: = | S29: =S28/S25 -> 20 | U29: A
A31: The CT requirement is as follows:
A33: Criteria I
B35: Vk | D35: >= | E35: 0.5 | F35: x | G35: Ifmax | I35: x ( | J35: Rct | L35: + | M35: Rb' | O35: )
D36: = | E36: 0.5 | F36: x | G36: =S26 -> 20 | I36: x ( | J36: =H12 -> 5 | L36: + | M36: =S27 -> 1.1770224 | O36: )
D37: = | E37: =E36*G36*(J36+M36) -> 61.770224
A39: Criteria II
B41: Vk | D41: >= | E41: Ifmax int | G41: x ( | H41: Rct | J41: + | K41: Rb' | M41: )
D42: = | E42: =S29 -> 20 | G42: x ( | H42: =H12 -> 5 | J42: + | K42: =S27 -> 1.1770224 | M42: )
D43: = | E43: =E42*(H42+K42) -> 123.54045
A48: Adequacy Check
B50: Criteria I
F51: Available Vk | G51: =IF(E52>H52, ">","<") -> > | H51: Required Vk | L51: (Criteria I)
E52: =H13 -> 750 | G52: =G51 -> > | H52: =E37 -> 61.770224
F53: Hence: | H53: Criteria I | J53: is | K53: =IF(G52=">", "Satisfied", "Not Satisfied") -> Satisfied
B54: Criteria II
F55: Available Vk | G55: =IF(E56>H56, ">","<") -> > | H55: Required Vk | L55: (Criteria II)
...

Sheet BCU+OC-5P SEL751+7SJ85 (2)
A1: HITACHI | H1: =Title!H1 -> CT / VT | O1: =Title!O1 -> Contract No. | R1: =Title!R1 -> N-19957.2-DF4W
H2: =Title!H2 -> ADEQUACY CHECK | O2: =Title!O2 -> Date | R2: =Title!R2 -> 46134
H3: =Title!H3 -> 132/33kV SUBSTATION DF4W AT AL DHAFRA AREA | O3: =Title!O3 -> Document No. | R3: =Title!R3 -> -
O4: =Title!O4 -> Revision No. | R4: =Title!R4 -> A
A5: =Title!A5 -> Prep. By | C5: =Title!C5 -> AP | D5: =Title!D5 -> Checked By | G5: =Title!G5 -> RB | H5: 33kV CABLE FEEDERS | O5: =Title!O5 -> Contractor | R5: =Title!R5 -> HITACHI
B7: T1 | D7: Core2 | H7: (OC +BCU) | S7: Connected devices: | T7: 7SJ85
T8: SEL751
H9: Tap-1 | J9: Tap-2 | L9: Tap-3
B10: CT Ratio: | H10: 600 | J10: 200 | L10: - | N10: / | O10: 1 | P10: A
B11: Class of Accuracy: | H11: 5P | I11: 20
B12: CT Resistance: | G12: Rct< | H12: 8 | J12: W
B13: Rated Burden | G13: PN | H13: 7.5 | J13: VA | W13: =G42 -> Under Dimensioned | AC13: 5
A15: Other Burdens on same CT core:
B17: Burden of | D17: =T7 -> 7SJ85 | I17: = | J17: ='CT-VT Burdens'!Q110 -> 0.02 | L17: VA | N17: CT internal Burden
B18: Burden of | D18: =T8 -> SEL751 | I18: = | J18: ='CT-VT Burdens'!Q111 -> 0.02 | L18: VA
B19: Burden of | D19: =T9 -> 0 | I19: = | L19: VA
B20: Burden of | L20: VA | N20: PE | O20: = | P20: In | Q20: x | R20: In | S20: x | T20: Rct
B21: Total lead burden | I21: = | J21: ='CT-VT Burdens'!S24 -> 1.0770224 | L21: VA | O21: = | P21: =O10 -> 1 | Q21: x | R21: =O10 -> 1 | S21: x | T21: =H12 -> 8
B22: Total lead + other burden | H22: PL | I22: = | J22: =SUM(J17:J21) -> 1.1170224 | L22: VA | O22: = | P22: =P21*R21*T21 -> 8 | R22: VA
C24: Max through fault current at close in fault | Q24: Itkmax | R24: = | S24: ='Parameters & Fault Cal. (4)'!Q10*1000 -> 50000 | U24: A | V24: ** | X24: This Current Must be Linked Later to Fault Setting
C25: CT Primary Current, | Q25: Ipn | R25: = | S25: =H10 -> 600 | U25: A
C26: Internal Burden, | Q26: PE | R26: = | S26: =P22 -> 8 | U26: VA
C27: Burden of CT Leads and burden of connected devices | Q27: PL | R27: = | S27: =J22 -> 1.1170224 | U27: VA
C28: Rated Secondary Current, | Q28: In | R28: = | S28: =O10 -> 1 | U28: A
C29: CT Accuracy Limiting Factor | Q29: n | R29: = | S29: =I11 -> 20
C30: CT Burden | Q30: PN | R30: = | S30: =H13 -> 7.5 | U30: VA
E32: Required Kssc' | F32: = | G32: Itkmax | I32: / | J32: Ipn
F33: = | G33: =S24 -> 50000 | I33: / | J33: =S25 -> 600
F34: = | G34: =G33/J33 -> 83.333333
E36: Available (effective) Kssc' | F36: = | G36: n | H36: x ( ( | I36: PE | J36: + | K36: PN | L36: ) / ( | M36: PE | N36: + | O36: PL | P36: )
F37: = | G37: =S29 -> 20 | H37: x ( ( | I37: =S26 -> 8 | J37: + | K37: =S30 -> 7.5 | L37: ) / ( | M37: =S26 -> 8 | N37: + | O37: =S27 -> 1.1170224 | P37: )
F38: = | G38: =G37*((I37+K37)/(M37+O37)) -> 34.002329
E40: Available Kssc' | F40: =IF(D41>G41,">","<") -> < | G40: Required Kssc'
D41: =G38 -> 34.002329 | F41: =F40 -> < | G41: =G34 -> 83.333333
E42: Hence CT is: | G42: =IF(F40=">","Suitably Dimensioned","Under Dimensioned") -> Under Dimensioned
J45: ** Assumed
B48: =B7 -> T1 | D48: =D7 -> Core2 | H48: =H7 -> (OC +BCU) | S48: Connected devices: | T48: =T7 -> 7SJ85
B49: =B8 -> 0 | T49: =T8 -> SEL751
H50: Tap-1 | J50: Tap-2 | L50: Tap-3 | T50: =T9 -> 0
B51: CT Ratio: | H51: =H10 -> 600 | J51: =J10 -> 200 | L51: =L10 -> - | N51: / | O51: =O10 -> 1 | P51: A | T51: =T10 -> 0
...

Sheet Tariff Check-0.2FS  (3)
A1: HITACHI | H1: =Title!H1 -> CT / VT | O1: =Title!O1 -> Contract No. | R1: =Title!R1 -> N-19957.2-DF4W
H2: =Title!H2 -> ADEQUACY CHECK | O2: =Title!O2 -> Date | R2: =Title!R2 -> 46134
